Workbook

Sheet INPUT
A1: 艇番 | B1: 選手名 | C1: 勝率 | D1: 当地勝率 | E1: モーター | F1: ボート | G1: ST | H1: 今節ST偏差 | I1: フライング | J1: 級別 | K1: 支部 | L1: 勝率評価(10) | M1: 当地評価(5) | N1: モーター評価(5) | O1: ボート評価(5) | P1: ST評価(5) | Q1: 地力スコア | R1: 足スコア | S1: スタートスコア | T1: フライングスコア | U1: 偏差ペナルティ | V1: 一次総合スコア | W1: タイプ分類 | X1: 一次評価
A2: 1 | B2: =TRIM(C24) -> 屋良 龍紀 | C2: =E23 -> 3.78 | D2: =F23 -> 4.02 | E2: =G24 -> 46.32 | F2: =H24 -> 39.42 | G2: =D25 -> 0.15 | H2: =STDEV(I25:T25) -> 0.040414519 | I2: =D23 -> F0 | J2: =RIGHT(C23,2) -> B1 | K2: =LEFT(C25,3) -> 長崎/ | L2: =MIN(10, MAX(1, C2 * 1.2)) -> 4.536 | M2: =MIN(5, MAX(1, (D2 - 4) * 2)) -> 1 | N2: =MIN(5, MAX(1, (E2 - 25) / 4)) -> 5 | O2: =MIN(5, MAX(1, (F2 - 25) / 4)) -> 3.605 | P2: =MIN(5, MAX(1, 8 - (G2 * 30))) -> 3.5 | Q2: =L2 + M2 -> 5.536 | R2: =N2 + O2 -> 8.605 | S2: =P2 -> 3.5 | T2: =IF(I2="F1",-5,IF(I2="F2",-10,IF(I2="F3",-15,0))) -> 0 | U2: =IF(H2 > 0.05, -5, 0) -> 0 | V2: =Q2 + R2 + S2+T2+U2 -> 17.641 | W2: {=_xlfn.IFS( A2=1, IF(V2>=22,4, IF(V2>=18,5, 6)), A2=6, IF(V2>=22,11, IF(V2>=18,12, 13)), V2>=22, IF(L2>=8,1,2), V2>=20, 3, AND(L2<=3, R2>=7), 14, AND(L2>=7, R2<=5), 15, P2=5, 17, V2>=18, 8, V2>=15, 9, TRUE, 10 )} -> 6 | X2: {=_xlfn.IFS( W2=1,"◎", W2=2,"○", W2=3,"○", W2=4,"◎", W2=5,"○", W2=6,"×", W2=7,"△", W2=8,"○", W2=9,"△", W2=10,"×", W2=11,"△", W2=12,"△", W2=13,"×", W2=14,"△", W2=15,"△", W2=16,"△", W2=17,"○", W2=18,"△" )} -> ×
A3: 2 | B3: =TRIM(C28) -> 大塚 康雅 | C3: =E27 -> 4.87 | D3: =F27 -> 5.23 | E3: =G28 -> 33.33 | F3: =H28 -> 27.86 | G3: =D29 -> 0.18 | H3: =STDEV(I29:T29) -> 0.077674535 | I3: =D27 -> F0 | J3: =RIGHT(C27,2) -> B1 | K3: =LEFT(C29,3) -> 東京/ | L3: =MIN(10, MAX(1, C3 * 1.2)) -> 5.844 | M3: =MIN(5, MAX(1, (D3 - 4) * 2)) -> 2.46 | N3: =MIN(5, MAX(1, (E3 - 25) / 4)) -> 2.0825 | O3: =MIN(5, MAX(1, (F3 - 25) / 4)) -> 1 | P3: =MIN(5, MAX(1, 8 - (G3 * 30))) -> 2.6 | Q3: =L3 + M3 -> 8.304 | R3: =N3 + O3 -> 3.0825 | S3: =P3 -> 2.6 | T3: =IF(I3="F1",-5,IF(I3="F2",-10,IF(I3="F3",-15,0))) -> 0 | U3: =IF(H3 > 0.05, -5, 0) -> -5 | V3: =Q3 + R3 + S3+T3+U3 -> 8.9865 | W3: {=_xlfn.IFS( A3=1, IF(V3>=22,4, IF(V3>=18,5, 6)), A3=6, IF(V3>=22,11, IF(V3>=18,12, 13)), V3>=22, IF(L3>=8,1,2), V3>=20, 3, AND(L3<=3, R3>=7), 14, AND(L3>=7, R3<=5), 15, P3=5, 17, V3>=18, 8, V3>=15, 9, TRUE, 10 )} -> 10 | X3: {=_xlfn.IFS( W3=1,"◎", W3=2,"○", W3=3,"○", W3=4,"◎", W3=5,"○", W3=6,"×", W3=7,"△", W3=8,"○", W3=9,"△", W3=10,"×", W3=11,"△", W3=12,"△", W3=13,"×", W3=14,"△", W3=15,"△", W3=16,"△", W3=17,"○", W3=18,"△" )} -> ×
A4: 3 | B4: =TRIM(C32) -> 上田 隆章 | C4: =E31 -> 4.56 | D4: =F31 -> 0 | E4: =G32 -> 27.89 | F4: =H32 -> 34.53 | G4: =D33 -> 0.23 | H4: =STDEV(I33:T33) -> 0.023094011 | I4: =D31 -> F0 | J4: =RIGHT(C31,2) -> B1 | K4: =LEFT(C33,3) -> 香川/ | L4: =MIN(10, MAX(1, C4 * 1.2)) -> 5.472 | M4: =MIN(5, MAX(1, (D4 - 4) * 2)) -> 1 | N4: =MIN(5, MAX(1, (E4 - 25) / 4)) -> 1 | O4: =MIN(5, MAX(1, (F4 - 25) / 4)) -> 2.3825 | P4: =MIN(5, MAX(1, 8 - (G4 * 30))) -> 1.1 | Q4: =L4 + M4 -> 6.472 | R4: =N4 + O4 -> 3.3825 | S4: =P4 -> 1.1 | T4: =IF(I4="F1",-5,IF(I4="F2",-10,IF(I4="F3",-15,0))) -> 0 | U4: =IF(H4 > 0.05, -5, 0) -> 0 | V4: =Q4 + R4 + S4+T4+U4 -> 10.9545 | W4: {=_xlfn.IFS( A4=1, IF(V4>=22,4, IF(V4>=18,5, 6)), A4=6, IF(V4>=22,11, IF(V4>=18,12, 13)), V4>=22, IF(L4>=8,1,2), V4>=20, 3, AND(L4<=3, R4>=7), 14, AND(L4>=7, R4<=5), 15, P4=5, 17, V4>=18, 8, V4>=15, 9, TRUE, 10 )} -> 10 | X4: {=_xlfn.IFS( W4=1,"◎", W4=2,"○", W4=3,"○", W4=4,"◎", W4=5,"○", W4=6,"×", W4=7,"△", W4=8,"○", W4=9,"△", W4=10,"×", W4=11,"△", W4=12,"△", W4=13,"×", W4=14,"△", W4=15,"△", W4=16,"△", W4=17,"○", W4=18,"△" )} -> ×
A5: 4 | B5: =TRIM(C36) -> 山田 和佐 | C5: =E35 -> 4.68 | D5: =F35 -> 4.38 | E5: =G36 -> 23.53 | F5: =H36 -> 32.86 | G5: =D37 -> 0.17 | H5: =STDEV(I37:T37) -> 0.05 | I5: =D35 -> F0 | J5: =RIGHT(C35,2) -> B1 | K5: =LEFT(C37,3) -> 広島/ | L5: =MIN(10, MAX(1, C5 * 1.2)) -> 5.616 | M5: =MIN(5, MAX(1, (D5 - 4) * 2)) -> 1 | N5: =MIN(5, MAX(1, (E5 - 25) / 4)) -> 1 | O5: =MIN(5, MAX(1, (F5 - 25) / 4)) -> 1.965 | P5: =MIN(5, MAX(1, 8 - (G5 * 30))) -> 2.9 | Q5: =L5 + M5 -> 6.616 | R5: =N5 + O5 -> 2.965 | S5: =P5 -> 2.9 | T5: =IF(I5="F1",-5,IF(I5="F2",-10,IF(I5="F3",-15,0))) -> 0 | U5: =IF(H5 > 0.05, -5, 0) -> -5 | V5: =Q5 + R5 + S5+T5+U5 -> 7.481 | W5: {=_xlfn.IFS( A5=1, IF(V5>=22,4, IF(V5>=18,5, 6)), A5=6, IF(V5>=22,11, IF(V5>=18,12, 13)), V5>=22, IF(L5>=8,1,2), V5>=20, 3, AND(L5<=3, R5>=7), 14, AND(L5>=7, R5<=5), 15, P5=5, 17, V5>=18, 8, V5>=15, 9, TRUE, 10 )} -> 10 | X5: {=_xlfn.IFS( W5=1,"◎", W5=2,"○", W5=3,"○", W5=4,"◎", W5=5,"○", W5=6,"×", W5=7,"△", W5=8,"○", W5=9,"△", W5=10,"×", W5=11,"△", W5=12,"△", W5=13,"×", W5=14,"△", W5=15,"△", W5=16,"△", W5=17,"○", W5=18,"△" )} -> ×
A6: 5 | B6: =TRIM(C40) -> 増本 杏珠 | C6: =E39 -> 3.39 | D6: =F39 -> 2.94 | E6: =G40 -> 27.34 | F6: =H40 -> 39.69 | G6: =D41 -> 0.17 | H6: =STDEV(I41:T41) -> 0 | I6: =D39 -> F1 | J6: =RIGHT(C39,2) -> B1 | K6: =LEFT(C41,3) -> 福岡/ | L6: =MIN(10, MAX(1, C6 * 1.2)) -> 4.068 | M6: =MIN(5, MAX(1, (D6 - 4) * 2)) -> 1 | N6: =MIN(5, MAX(1, (E6 - 25) / 4)) -> 1 | O6: =MIN(5, MAX(1, (F6 - 25) / 4)) -> 3.6725 | P6: =MIN(5, MAX(1, 8 - (G6 * 30))) -> 2.9 | Q6: =L6 + M6 -> 5.068 | R6: =N6 + O6 -> 4.6725 | S6: =P6 -> 2.9 | T6: =IF(I6="F1",-5,IF(I6="F2",-10,IF(I6="F3",-15,0))) -> -5 | U6: =IF(H6 > 0.05, -5, 0) -> 0 | V6: =Q6 + R6 + S6+T6+U6 -> 7.6405 | W6: {=_xlfn.IFS( A6=1, IF(V6>=22,4, IF(V6>=18,5, 6)), A6=6, IF(V6>=22,11, IF(V6>=18,12, 13)), V6>=22, IF(L6>=8,1,2), V6>=20, 3, AND(L6<=3, R6>=7), 14, AND(L6>=7, R6<=5), 15, P6=5, 17, V6>=18, 8, V6>=15, 9, TRUE, 10 )} -> 10 | X6: {=_xlfn.IFS( W6=1,"◎", W6=2,"○", W6=3,"○", W6=4,"◎", W6=5,"○", W6=6,"×", W6=7,"△", W6=8,"○", W6=9,"△", W6=10,"×", W6=11,"△", W6=12,"△", W6=13,"×", W6=14,"△", W6=15,"△", W6=16,"△", W6=17,"○", W6=18,"△" )} -> ×
A7: 6 | B7: =TRIM(C44) -> 大西 隆洋 | C7: =E43 -> 3.46 | D7: =F43 -> 1.4 | E7: =G44 -> 27.46 | F7: =H44 -> 34.07 | G7: =D45 -> 0.16 | H7: =STDEV(I45:T45) -> 0.025166115 | I7: =D43 -> F0 | J7: =RIGHT(C43,2) -> B1 | K7: =LEFT(C45,3) -> 香川/ | L7: =MIN(10, MAX(1, C7 * 1.2)) -> 4.152 | M7: =MIN(5, MAX(1, (D7 - 4) * 2)) -> 1 | N7: =MIN(5, MAX(1, (E7 - 25) / 4)) -> 1 | O7: =MIN(5, MAX(1, (F7 - 25) / 4)) -> 2.2675 | P7: =MIN(5, MAX(1, 8 - (G7 * 30))) -> 3.2 | Q7: =L7 + M7 -> 5.152 | R7: =N7 + O7 -> 3.2675 | S7: =P7 -> 3.2 | T7: =IF(I7="F1",-5,IF(I7="F2",-10,IF(I7="F3",-15,0))) -> 0 | U7: =IF(H7 > 0.05, -5, 0) -> 0 | V7: =Q7 + R7 + S7+T7+U7 -> 11.6195 | W7: {=_xlfn.IFS( A7=1, IF(V7>=22,4, IF(V7>=18,5, 6)), A7=6, IF(V7>=22,11, IF(V7>=18,12, 13)), V7>=22, IF(L7>=8,1,2), V7>=20, 3, AND(L7<=3, R7>=7), 14, AND(L7>=7, R7<=5), 15, P7=5, 17, V7>=18, 8, V7>=15, 9, TRUE, 10 )} -> 13 | X7: {=_xlfn.IFS( W7=1,"◎", W7=2,"○", W7=3,"○", W7=4,"◎", W7=5,"○", W7=6,"×", W7=7,"△", W7=8,"○", W7=9,"△", W7=10,"×", W7=11,"△", W7=12,"△", W7=13,"×", W7=14,"△", W7=15,"△", W7=16,"△", W7=17,"○", W7=18,"△" )} -> ×
A14: ここに公式から出走表を張り付ける
A16: 枠 | B16: ボートレーサー | E16: 全国 | F16: 当地 | G16: モーター | H16: ボート | J16: レースNo（艇番色） | X16: 早見
J17: 進入コース
J18: STタイミング
B19: 写真 | C19: 登録番号/級別 | D19: F数 | E19: 勝率 | F19: 勝率 | G19: No | H19: No | J19: 成績
C20: 氏名 | D20: L数 | E20: 2連率 | F20: 2連率 | G20: 2連率 | H20: 2連率
C21: 支部/出身地 | D21: 平均ST | E21: 3連率 | F21: 3連率 | G21: 3連率 | H21: 3連率
C22: 年齢/体重 | J22: 初日 | L22: ２日目 | N22: ３日目 | P22: ４日目 | R22: ５日目 | T22: ６日目 | V22: 最終日
A23: 1 | C23: 5208 / B1 | D23: F0 | E23: 3.78 | F23: 4.02 | G23: 21 | H23: 66 | J23: 1 | K23: 7 | L23: 6 | X23: 11R
C24: 屋良 龍紀 | D24: L0 | E24: 19.48 | F24: 27.27 | G24: 46.32 | H24: 39.42 | J24: 6 | K24: 4 | L24: 2
C25: 長崎/長崎 | D25: 0.15 | E25: 31.17 | F25: 32.73 | G25: 60.29 | H25: 56.2 | J25: 0.11 | K25: 0.08 | L25: 0.16
C26: 28歳/51.5kg | J26: 3 | K26: 3 | L26: 3
A27: 2 | C27: 4875 / B1 | D27: F0 | E27: 4.87 | F27: 5.23 | G27: 44 | H27: 13 | J27: 3 | L27: 2 | M27: 7
C28: 大塚 康雅 | D28: L0 | E28: 26.83 | F28: 30.77 | G28: 33.33 | H28: 27.86 | J28: 1 | L28: 4 | M28: 3
C29: 東京/神奈川 | D29: 0.18 | E29: 43.9 | F29: 46.15 | G29: 51.11 | H29: 43.57 | J29: 0.3 | L29: 0.15 | M29: 0.26
C30: 31歳/50.5kg | J30: 6 | L30: 4 | M30: 5
A31: 3 | C31: 3401 / B1 | D31: F0 | E31: 4.56 | F31: 0 | G31: 67 | H31: 30 | J31: 5 | K31: 10 | L31: 2 | X31: 7R
C32: 上田 隆章 | D32: L0 | E32: 26.6 | F32: 0 | G32: 27.89 | H32: 34.53 | J32: 5 | K32: 2 | L32: 1
C33: 香川/高知 | D33: 0.23 | E33: 40.43 | F33: 0 | G33: 42.86 | H33: 55.4 | J33: 0.23 | K33: 0.23 | L33: 0.19
C34: 58歳/52.1kg | J34: 4 | K34: 6 | L34: 1
A35: 4 | C35: 4978 / B1 | D35: F0 | E35: 4.68 | F35: 4.38 | G35: 37 | H35: 62 | J35: 3 | K35: 10 | L35: 8 | X35: 9R
C36: 山田 和佐 | D36: L0 | E36: 24.55 | F36: 20.83 | G36: 23.53 | H36: 32.86 | J36: 2 | K36: 6 | L36: 5
C37: 広島/島根 | D37: 0.17 | E37: 44.55 | F37: 41.67 | G37: 41.18 | H37: 50.71 | J37: 0.29 | K37: 0.19 | L37: 0.24
C38: 31歳/52.7kg | J38: 3 | K38: 5 | L38: 5
A39: 5 | C39: 5358 / B1 | D39: F1 | E39: 3.39 | F39: 2.94 | G39: 50 | H39: 18 | J39: 9 | L39: 7 | X39: 10R
C40: 増本 杏珠 | D40: L0 | E40: 8.11 | F40: 9.38 | G40: 27.34 | H40: 39.69 | J40: 4 | L40: 6
C41: 福岡/福岡 | D41: 0.17 | E41: 25.68 | F41: 15.63 | G41: 43.17 | H41: 55.73 | J41: 0.3 | L41: 0.3
C42: 20歳/49.1kg | J42: 4 | L42: 4
A43: 6 | C43: 3701 / B1 | D43: F0 | E43: 3.46 | F43: 1.4 | G43: 51 | H43: 53 | J43: 1 | K43: 6 | L43: 6 | X43: 6R
C44: 大西 隆洋 | D44: L0 | E44: 12.5 | F44: 0 | G44: 27.46 | H44: 34.07 | J44: 1 | K44: 4 | L44: 5
C45: 香川/愛媛 | D45: 0.16 | E45: 22.5 | F45: 0 | G45: 41.55 | H45: 49.63 | J45: 0.14 | K45: 0.12 | L45: 0.17
C46: 52歳/55.5kg | J46: 2 | K46: 6 | L46: 4
A47: 今節成績
...

Sheet INPUT (2)
A1: 艇番 | B1: 選手名 | C1: 勝率 | D1: 当地勝率 | E1: モーター | F1: ボート | G1: ST | H1: 級別 | I1: 支部 | J1: 勝率評価(10) | K1: 当地評価(5) | L1: モーター評価(5) | M1: ボート評価(5) | N1: ST評価(5) | O1: 地力スコア | P1: 足スコア | Q1: スタートスコア | R1: 一次総合スコア | S1: タイプ分類 | T1: 一次評価
A2: 1 | B2: =TRIM(C120) -> 中野 希一 | C2: =E119 -> 6.93 | D2: =F119 -> 6.63 | E2: =G120 -> 34.58 | F2: =H120 -> 43.18 | G2: =D121 -> 0.13 | H2: =RIGHT(C119,2) -> A1 | I2: =LEFT(C121,3) -> 埼玉/ | J2: =MIN(10, MAX(1, C2 * 1.2)) | K2: =MIN(5, MAX(1, (D2 - 4) * 2)) | L2: =MIN(5, MAX(1, (E2 - 25) / 4)) | M2: =MIN(5, MAX(1, (F2 - 25) / 4)) | N2: =MIN(5, MAX(1, 8 - (G2 * 30))) | O2: =J2 + K2 | P2: =L2 + M2 | Q2: =N2 | R2: =O2 + P2 + Q2+#REF!+#REF! | S2: =IFS( A2=1, IF(R2>=22,4, IF(R2>=18,5, 6)), A2=6, IF(R2>=22,11, IF(R2>=18,12, 13)), R2>=22, IF(J2>=8,1,2), R2>=20, 3, AND(J2<=3, P2>=7), 14, AND(J2>=7, P2<=5), 15, N2=5, 17, R2>=18, 8, R2>=15, 9, TRUE, 10 ) | T2: =IFS( S2=1,"◎", S2=2,"○", S2=3,"○", S2=4,"◎", S2=5,"○", S2=6,"×", S2=7,"△", S2=8,"○", S2=9,"△", S2=10,"×", S2=11,"△", S2=12,"△", S2=13,"×", S2=14,"△", S2=15,"△", S2=16,"△", S2=17,"○", S2=18,"△" )
A3: 2 | B3: =TRIM(C124) -> 石塚 久也 | C3: =E123 -> 5.78 | D3: =F123 -> 6.79 | E3: =G124 -> 32.43 | F3: =H124 -> 36.05 | G3: =D125 -> 0.19 | H3: =RIGHT(C123,2) -> A2 | I3: =LEFT(C125,3) -> 埼玉/ | J3: =MIN(10, MAX(1, C3 * 1.2)) | K3: =MIN(5, MAX(1, (D3 - 4) * 2)) | L3: =MIN(5, MAX(1, (E3 - 25) / 4)) | M3: =MIN(5, MAX(1, (F3 - 25) / 4)) | N3: =MIN(5, MAX(1, 8 - (G3 * 30))) | O3: =J3 + K3 | P3: =L3 + M3 | Q3: =N3 | R3: =O3 + P3 + Q3+#REF!+#REF! | S3: =IFS( A3=1, IF(R3>=22,4, IF(R3>=18,5, 6)), A3=6, IF(R3>=22,11, IF(R3>=18,12, 13)), R3>=22, IF(J3>=8,1,2), R3>=20, 3, AND(J3<=3, P3>=7), 14, AND(J3>=7, P3<=5), 15, N3=5, 17, R3>=18, 8, R3>=15, 9, TRUE, 10 ) | T3: =IFS( S3=1,"◎", S3=2,"○", S3=3,"○", S3=4,"◎", S3=5,"○", S3=6,"×", S3=7,"△", S3=8,"○", S3=9,"△", S3=10,"×", S3=11,"△", S3=12,"△", S3=13,"×", S3=14,"△", S3=15,"△", S3=16,"△", S3=17,"○", S3=18,"△" )
A4: 3 | B4: =TRIM(C128) -> 中田 竜太 | C4: =E127 -> 6.21 | D4: =F127 -> 7.01 | E4: =G128 -> 32.93 | F4: =H128 -> 40.22 | G4: =D129 -> 0.15 | H4: =RIGHT(C127,2) -> A1 | I4: =LEFT(C129,3) -> 埼玉/ | J4: =MIN(10, MAX(1, C4 * 1.2)) | K4: =MIN(5, MAX(1, (D4 - 4) * 2)) | L4: =MIN(5, MAX(1, (E4 - 25) / 4)) | M4: =MIN(5, MAX(1, (F4 - 25) / 4)) | N4: =MIN(5, MAX(1, 8 - (G4 * 30))) | O4: =J4 + K4 | P4: =L4 + M4 | Q4: =N4 | R4: =O4 + P4 + Q4+#REF!+#REF! | S4: =IFS( A4=1, IF(R4>=22,4, IF(R4>=18,5, 6)), A4=6, IF(R4>=22,11, IF(R4>=18,12, 13)), R4>=22, IF(J4>=8,1,2), R4>=20, 3, AND(J4<=3, P4>=7), 14, AND(J4>=7, P4<=5), 15, N4=5, 17, R4>=18, 8, R4>=15, 9, TRUE, 10 ) | T4: =IFS( S4=1,"◎", S4=2,"○", S4=3,"○", S4=4,"◎", S4=5,"○", S4=6,"×", S4=7,"△", S4=8,"○", S4=9,"△", S4=10,"×", S4=11,"△", S4=12,"△", S4=13,"×", S4=14,"△", S4=15,"△", S4=16,"△", S4=17,"○", S4=18,"△" )
A5: 4 | B5: =TRIM(C132) -> 佐藤 翼 | C5: =E131 -> 6.53 | D5: =F131 -> 7.93 | E5: =G132 -> 35 | F5: =H132 -> 31.03 | G5: =D133 -> 0.13 | H5: =RIGHT(C131,2) -> A1 | I5: =LEFT(C133,3) -> 埼玉/ | J5: =MIN(10, MAX(1, C5 * 1.2)) | K5: =MIN(5, MAX(1, (D5 - 4) * 2)) | L5: =MIN(5, MAX(1, (E5 - 25) / 4)) | M5: =MIN(5, MAX(1, (F5 - 25) / 4)) | N5: =MIN(5, MAX(1, 8 - (G5 * 30))) | O5: =J5 + K5 | P5: =L5 + M5 | Q5: =N5 | R5: =O5 + P5 + Q5+#REF!+#REF! | S5: =IFS( A5=1, IF(R5>=22,4, IF(R5>=18,5, 6)), A5=6, IF(R5>=22,11, IF(R5>=18,12, 13)), R5>=22, IF(J5>=8,1,2), R5>=20, 3, AND(J5<=3, P5>=7), 14, AND(J5>=7, P5<=5), 15, N5=5, 17, R5>=18, 8, R5>=15, 9, TRUE, 10 ) | T5: =IFS( S5=1,"◎", S5=2,"○", S5=3,"○", S5=4,"◎", S5=5,"○", S5=6,"×", S5=7,"△", S5=8,"○", S5=9,"△", S5=10,"×", S5=11,"△", S5=12,"△", S5=13,"×", S5=14,"△", S5=15,"△", S5=16,"△", S5=17,"○", S5=18,"△" )
A6: 5 | B6: =TRIM(C136) -> 飛田 江己 | C6: =E135 -> 6.61 | D6: =F135 -> 6.51 | E6: =G136 -> 40.21 | F6: =H136 -> 30.11 | G6: =D137 -> 0.13 | H6: =RIGHT(C135,2) -> A1 | I6: =LEFT(C137,3) -> 埼玉/ | J6: =MIN(10, MAX(1, C6 * 1.2)) | K6: =MIN(5, MAX(1, (D6 - 4) * 2)) | L6: =MIN(5, MAX(1, (E6 - 25) / 4)) | M6: =MIN(5, MAX(1, (F6 - 25) / 4)) | N6: =MIN(5, MAX(1, 8 - (G6 * 30))) | O6: =J6 + K6 | P6: =L6 + M6 | Q6: =N6 | R6: =O6 + P6 + Q6+#REF!+#REF! | S6: =IFS( A6=1, IF(R6>=22,4, IF(R6>=18,5, 6)), A6=6, IF(R6>=22,11, IF(R6>=18,12, 13)), R6>=22, IF(J6>=8,1,2), R6>=20, 3, AND(J6<=3, P6>=7), 14, AND(J6>=7, P6<=5), 15, N6=5, 17, R6>=18, 8, R6>=15, 9, TRUE, 10 ) | T6: =IFS( S6=1,"◎", S6=2,"○", S6=3,"○", S6=4,"◎", S6=5,"○", S6=6,"×", S6=7,"△", S6=8,"○", S6=9,"△", S6=10,"×", S6=11,"△", S6=12,"△", S6=13,"×", S6=14,"△", S6=15,"△", S6=16,"△", S6=17,"○", S6=18,"△" )
A7: 6 | B7: =TRIM(C140) -> 佐藤 航 | C7: =E139 -> 6.22 | D7: =F139 -> 5.57 | E7: =G140 -> 41.58 | F7: =H140 -> 45.05 | G7: =D141 -> 0.15 | H7: =RIGHT(C139,2) -> A2 | I7: =LEFT(C141,3) -> 埼玉/ | J7: =MIN(10, MAX(1, C7 * 1.2)) | K7: =MIN(5, MAX(1, (D7 - 4) * 2)) | L7: =MIN(5, MAX(1, (E7 - 25) / 4)) | M7: =MIN(5, MAX(1, (F7 - 25) / 4)) | N7: =MIN(5, MAX(1, 8 - (G7 * 30))) | O7: =J7 + K7 | P7: =L7 + M7 | Q7: =N7 | R7: =O7 + P7 + Q7+#REF!+#REF! | S7: =IFS( A7=1, IF(R7>=22,4, IF(R7>=18,5, 6)), A7=6, IF(R7>=22,11, IF(R7>=18,12, 13)), R7>=22, IF(J7>=8,1,2), R7>=20, 3, AND(J7<=3, P7>=7), 14, AND(J7>=7, P7<=5), 15, N7=5, 17, R7>=18, 8, R7>=15, 9, TRUE, 10 ) | T7: =IFS( S7=1,"◎", S7=2,"○", S7=3,"○", S7=4,"◎", S7=5,"○", S7=6,"×", S7=7,"△", S7=8,"○", S7=9,"△", S7=10,"×", S7=11,"△", S7=12,"△", S7=13,"×", S7=14,"△", S7=15,"△", S7=16,"△", S7=17,"○", S7=18,"△" )
A9: 大前提：race_codeが全体を紐づけるもの。YYYYMMDD+場コード+レース番号となる。例:2026/1/25の大村1Rの場合→20260124OMR01
A10: 艇番 | B10: boat_race.race_entry | C10: lane_number
A11: 選手名 | B11: boat_race.race_entry | C11: player_name
A12: 勝率 | B12: boat_race.player_stats | C12: national_win_rate
A13: 当地勝率 | B13: boat_race.player_stats | C13: local_win_rate
A14: モーター | B14: boat_race.engine_specs | C14: motor_exacta_rate
A15: ボート | B15: boat_race.engine_specs | C15: boat_exacta_rate
A16: ST | B16: boat_race.racer_results | C16: average_start | D16: term_infoが最新のものを対象
A17: 今節ST偏差 | B17: - | C17: - | D17: 不要
A18: フライング | B18: - | C18: - | D18: 未取得
A19: 級別 | B19: boat_race.racer_results | C19: class | D19: term_infoが最新のものを対象
A20: 支部 | B20: boat_race.racer_results | C20: branch | D20: term_infoが最新のものを対象
A21: 勝率評価(10) | B21: 数式
A22: 当地評価(5) | B22: 数式
A23: モーター評価(5) | B23: 数式
A24: ボート評価(5) | B24: 数式
A25: ST評価(5) | B25: 数式
A26: 地力スコア | B26: 数式
A27: 足スコア | B27: 数式
A28: スタートスコア | B28: 数式
A29: フライングスコア | B29: 数式 | D29: 不要
A30: 偏差ペナルティ | B30: 数式 | D30: 不要
A31: 一次総合スコア | B31: 数式
A32: タイプ分類 | B32: 数式
A33: 一次評価 | B33: 数式
A110: ここに公式から出走表を張り付ける
A112: 枠 | B112: ボートレーサー | E112: 全国 | F112: 当地 | G112: モーター | H112: ボート | J112: レースNo（艇番色） | X112: 早見
J113: 進入コース
J114: STタイミング
B115: 写真 | C115: 登録番号/級別 | D115: F数 | E115: 勝率 | F115: 勝率 | G115: No | H115: No | J115: 成績
C116: 氏名 | D116: L数 | E116: 2連率 | F116: 2連率 | G116: 2連率 | H116: 2連率
C117: 支部/出身地 | D117: 平均ST | E117: 3連率 | F117: 3連率 | G117: 3連率 | H117: 3連率
C118: 年齢/体重 | J118: 初日 | L118: ２日目 | N118: ３日目 | P118: ４日目 | R118: ５日目 | T118: 最終日
...

Sheet Sheet4
A1: 艇番 | B1: 選手名 | C1: 勝率 | D1: 当地勝率 | E1: モーター | F1: ボート | G1: ST | H1: 級別 | I1: 支部 | J1: 勝率評価(10) | K1: 当地評価(5) | L1: モーター評価(5) | M1: ボート評価(5) | N1: ST評価(5) | O1: 地力スコア | P1: 足スコア | Q1: スタートスコア | R1: 一次総合スコア | S1: タイプ分類 | T1: 一次評価
A2: 1 | B2: 中野 希一 | C2: 6.93 | D2: 6.63 | E2: 34.58 | F2: 43.18 | G2: 0.13 | H2: A1 | I2: 埼玉/ | J2: 8.316 | K2: 5 | L2: 2.395 | M2: 4.545 | N2: 4.1 | O2: 13.316 | P2: 6.94 | Q2: 4.1 | R2: #REF! | S2: #REF! | T2: #REF!
A3: 2 | B3: 石塚 久也 | C3: 5.78 | D3: 6.79 | E3: 32.43 | F3: 36.05 | G3: 0.19 | H3: A2 | I3: 埼玉/ | J3: 6.936 | K3: 5 | L3: 1.8575 | M3: 2.7625 | N3: 2.3 | O3: 11.936 | P3: 4.62 | Q3: 2.3 | R3: #REF! | S3: #REF! | T3: #REF!
A4: 3 | B4: 中田 竜太 | C4: 6.21 | D4: 7.01 | E4: 32.93 | F4: 40.22 | G4: 0.15 | H4: A1 | I4: 埼玉/ | J4: 7.452 | K4: 5 | L4: 1.9825 | M4: 3.805 | N4: 3.5 | O4: 12.452 | P4: 5.7875 | Q4: 3.5 | R4: #REF! | S4: #REF! | T4: #REF!
A5: 4 | B5: 佐藤 翼 | C5: 6.53 | D5: 7.93 | E5: 35 | F5: 31.03 | G5: 0.13 | H5: A1 | I5: 埼玉/ | J5: 7.836 | K5: 5 | L5: 2.5 | M5: 1.5075 | N5: 4.1 | O5: 12.836 | P5: 4.0075 | Q5: 4.1 | R5: #REF! | S5: #REF! | T5: #REF!
A6: 5 | B6: 飛田 江己 | C6: 6.61 | D6: 6.51 | E6: 40.21 | F6: 30.11 | G6: 0.13 | H6: A1 | I6: 埼玉/ | J6: 7.932 | K6: 5 | L6: 3.8025 | M6: 1.2775 | N6: 4.1 | O6: 12.932 | P6: 5.08 | Q6: 4.1 | R6: #REF! | S6: #REF! | T6: #REF!
A7: 6 | B7: 佐藤 航 | C7: 6.22 | D7: 5.57 | E7: 41.58 | F7: 45.05 | G7: 0.15 | H7: A2 | I7: 埼玉/ | J7: 7.464 | K7: 3.14 | L7: 4.145 | M7: 5 | N7: 3.5 | O7: 10.604 | P7: 9.145 | Q7: 3.5 | R7: #REF! | S7: #REF! | T7: #REF!
A9: 大前提：race_codeが全体を紐づけるもの。YYYYMMDD+場コード+レース番号となる。例:2026/1/25の大村1Rの場合→20260124OMR01
A10: 艇番 | B10: boat_race.race_entry | C10: lane_number
A11: 選手名 | B11: boat_race.race_entry | C11: player_name
A12: 勝率 | B12: boat_race.player_stats | C12: national_win_rate
A13: 当地勝率 | B13: boat_race.player_stats | C13: local_win_rate
A14: モーター | B14: boat_race.engine_specs | C14: motor_exacta_rate
A15: ボート | B15: boat_race.engine_specs | C15: boat_exacta_rate
A16: ST | B16: boat_race.racer_results | C16: average_start | D16: term_infoが最新のものを対象
A17: 今節ST偏差 | B17: - | C17: - | D17: 不要
A18: フライング | B18: - | C18: - | D18: 未取得
A19: 級別 | B19: boat_race.racer_results | C19: class | D19: term_infoが最新のものを対象
A20: 支部 | B20: boat_race.racer_results | C20: branch | D20: term_infoが最新のものを対象
A21: 勝率評価(10) | B21: 数式
A22: 当地評価(5) | B22: 数式
A23: モーター評価(5) | B23: 数式
A24: ボート評価(5) | B24: 数式
A25: ST評価(5) | B25: 数式
A26: 地力スコア | B26: 数式
A27: 足スコア | B27: 数式
A28: スタートスコア | B28: 数式
A29: フライングスコア | B29: 数式 | D29: 不要
A30: 偏差ペナルティ | B30: 数式 | D30: 不要
A31: 一次総合スコア | B31: 数式
A32: タイプ分類 | B32: 数式
A33: 一次評価 | B33: 数式
A110: ここに公式から出走表を張り付ける
A112: 枠 | B112: ボートレーサー | E112: 全国 | F112: 当地 | G112: モーター | H112: ボート | J112: レースNo（艇番色） | X112: 早見
J113: 進入コース
J114: STタイミング
B115: 写真 | C115: 登録番号/級別 | D115: F数 | E115: 勝率 | F115: 勝率 | G115: No | H115: No | J115: 成績
C116: 氏名 | D116: L数 | E116: 2連率 | F116: 2連率 | G116: 2連率 | H116: 2連率
C117: 支部/出身地 | D117: 平均ST | E117: 3連率 | F117: 3連率 | G117: 3連率 | H117: 3連率
C118: 年齢/体重 | J118: 初日 | L118: ２日目 | N118: ３日目 | P118: ４日目 | R118: ５日目 | T118: 最終日
...

Sheet Sheet3
B2: 大前提：race_codeが全体を紐づけるもの。YYYYMMDD+場コード+レース番号となる。例:2026/1/25の大村1Rの場合→20260124OMR01
B3: 艇番 | C3: boat_race.race_entry | D3: lane_number
B4: 選手名 | C4: boat_race.race_entry | D4: player_name
B5: 勝率 | C5: boat_race.player_stats | D5: national_win_rate
B6: 当地勝率 | C6: boat_race.player_stats | D6: local_win_rate
B7: モーター | C7: boat_race.engine_specs | D7: motor_exacta_rate
B8: ボート | C8: boat_race.engine_specs | D8: boat_exacta_rate
B9: ST | C9: boat_race.racer_results | D9: average_start | E9: term_infoが最新のものを対象
B10: 今節ST偏差 | C10: - | D10: - | E10: 不要
B11: フライング | C11: - | D11: - | E11: 未取得
B12: 級別 | C12: boat_race.racer_results | D12: class | E12: term_infoが最新のものを対象
B13: 支部 | C13: boat_race.racer_results | D13: branch | E13: term_infoが最新のものを対象
B14: 勝率評価(10) | C14: 数式
B15: 当地評価(5) | C15: 数式
B16: モーター評価(5) | C16: 数式
B17: ボート評価(5) | C17: 数式
B18: ST評価(5) | C18: 数式
B19: 地力スコア | C19: 数式
B20: 足スコア | C20: 数式
B21: スタートスコア | C21: 数式
B22: フライングスコア | C22: 数式 | E22: 不要
B23: 偏差ペナルティ | C23: 数式 | E23: 不要
B24: 一次総合スコア | C24: 数式
B25: タイプ分類 | C25: 数式
B26: 一次評価 | C26: 数式

Sheet KIMARITE
A1: 枠 | B1: 期間 | C1: 逃げ | D1: 差し | E1: まくり | F1: まくり差し | G1: 逃し | H1: 差され | I1: 捲られ | J1: 捲られ差 | K1: 逃げ | L1: 差し | M1: まくり | N1: まくり差し | O1: 逃し | P1: 差され | Q1: 捲られ | R1: 捲られ差
A2: 1 | B2: 1年 | C2: =A20 -> 0.458 | D2: 0 | E2: 0 | F2: 0 | G2: 0 | H2: =A23 -> 0.186 | I2: =A27 -> 0.288 | J2: =A31 -> 0.017 | K2: =IFERROR(VALUE(SUBSTITUTE(C2, "%", "")), 0) -> 0.458 | L2: =IFERROR(VALUE(SUBSTITUTE(D2, "%", "")), 0) -> 0 | M2: =IFERROR(VALUE(SUBSTITUTE(E2, "%", "")), 0) -> 0 | N2: =IFERROR(VALUE(SUBSTITUTE(F2, "%", "")), 0) -> 0 | O2: =IFERROR(VALUE(SUBSTITUTE(G2, "%", "")), 0) -> 0 | P2: =IFERROR(VALUE(SUBSTITUTE(H2, "%", "")), 0) -> 0.186 | Q2: =IFERROR(VALUE(SUBSTITUTE(I2, "%", "")), 0) -> 0.288 | R2: =IFERROR(VALUE(SUBSTITUTE(J2, "%", "")), 0) -> 0.017
A3: 1 | B3: 6ヶ月 | C3: =A21 -> 0.563 | D3: 0 | E3: 0 | F3: 0 | G3: 0 | H3: =A24 -> 0.156 | I3: =A28 -> 0.25 | J3: =A32 -> 0.031 | K3: =IFERROR(VALUE(SUBSTITUTE(C3, "%", "")), 0) -> 0.563 | L3: =IFERROR(VALUE(SUBSTITUTE(D3, "%", "")), 0) -> 0 | M3: =IFERROR(VALUE(SUBSTITUTE(E3, "%", "")), 0) -> 0 | N3: =IFERROR(VALUE(SUBSTITUTE(F3, "%", "")), 0) -> 0 | O3: =IFERROR(VALUE(SUBSTITUTE(G3, "%", "")), 0) -> 0 | P3: =IFERROR(VALUE(SUBSTITUTE(H3, "%", "")), 0) -> 0.156 | Q3: =IFERROR(VALUE(SUBSTITUTE(I3, "%", "")), 0) -> 0.25 | R3: =IFERROR(VALUE(SUBSTITUTE(J3, "%", "")), 0) -> 0.031
A4: 2 | B4: 1年 | C4: 0 | D4: =C23 -> 0.175 | E4: =C27 -> 0.05 | F4: =C31 -> 0 | G4: =C20 -> 0.5 | H4: 0 | I4: 0 | J4: 0 | K4: =IFERROR(VALUE(SUBSTITUTE(C4, "%", "")), 0) -> 0 | L4: =IFERROR(VALUE(SUBSTITUTE(D4, "%", "")), 0) -> 0.175 | M4: =IFERROR(VALUE(SUBSTITUTE(E4, "%", "")), 0) -> 0.05 | N4: =IFERROR(VALUE(SUBSTITUTE(F4, "%", "")), 0) -> 0 | O4: =IFERROR(VALUE(SUBSTITUTE(G4, "%", "")), 0) -> 0.5 | P4: =IFERROR(VALUE(SUBSTITUTE(H4, "%", "")), 0) -> 0 | Q4: =IFERROR(VALUE(SUBSTITUTE(I4, "%", "")), 0) -> 0 | R4: =IFERROR(VALUE(SUBSTITUTE(J4, "%", "")), 0) -> 0
A5: 2 | B5: 6ヶ月 | C5: 0 | D5: =C24 -> 0.095 | E5: =C28 -> 0.048 | F5: =C32 -> 0 | G5: =C21 -> 0.524 | H5: 0 | I5: 0 | J5: 0 | K5: =IFERROR(VALUE(SUBSTITUTE(C5, "%", "")), 0) -> 0 | L5: =IFERROR(VALUE(SUBSTITUTE(D5, "%", "")), 0) -> 0.095 | M5: =IFERROR(VALUE(SUBSTITUTE(E5, "%", "")), 0) -> 0.048 | N5: =IFERROR(VALUE(SUBSTITUTE(F5, "%", "")), 0) -> 0 | O5: =IFERROR(VALUE(SUBSTITUTE(G5, "%", "")), 0) -> 0.524 | P5: =IFERROR(VALUE(SUBSTITUTE(H5, "%", "")), 0) -> 0 | Q5: =IFERROR(VALUE(SUBSTITUTE(I5, "%", "")), 0) -> 0 | R5: =IFERROR(VALUE(SUBSTITUTE(J5, "%", "")), 0) -> 0
A6: 3 | B6: 1年 | C6: 0 | D6: =D23 -> 0.033 | E6: =D27 -> 0.067 | F6: =D31 -> 0.067 | G6: 0 | H6: 0 | I6: 0 | J6: 0 | K6: =IFERROR(VALUE(SUBSTITUTE(C6, "%", "")), 0) -> 0 | L6: =IFERROR(VALUE(SUBSTITUTE(D6, "%", "")), 0) -> 0.033 | M6: =IFERROR(VALUE(SUBSTITUTE(E6, "%", "")), 0) -> 0.067 | N6: =IFERROR(VALUE(SUBSTITUTE(F6, "%", "")), 0) -> 0.067 | O6: =IFERROR(VALUE(SUBSTITUTE(G6, "%", "")), 0) -> 0 | P6: =IFERROR(VALUE(SUBSTITUTE(H6, "%", "")), 0) -> 0 | Q6: =IFERROR(VALUE(SUBSTITUTE(I6, "%", "")), 0) -> 0 | R6: =IFERROR(VALUE(SUBSTITUTE(J6, "%", "")), 0) -> 0
A7: 3 | B7: 6ヶ月 | C7: 0 | D7: =D24 -> 0.071 | E7: =D28 -> 0.071 | F7: =D32 -> 0.071 | G7: 0 | H7: 0 | I7: 0 | J7: 0 | K7: =IFERROR(VALUE(SUBSTITUTE(C7, "%", "")), 0) -> 0 | L7: =IFERROR(VALUE(SUBSTITUTE(D7, "%", "")), 0) -> 0.071 | M7: =IFERROR(VALUE(SUBSTITUTE(E7, "%", "")), 0) -> 0.071 | N7: =IFERROR(VALUE(SUBSTITUTE(F7, "%", "")), 0) -> 0.071 | O7: =IFERROR(VALUE(SUBSTITUTE(G7, "%", "")), 0) -> 0 | P7: =IFERROR(VALUE(SUBSTITUTE(H7, "%", "")), 0) -> 0 | Q7: =IFERROR(VALUE(SUBSTITUTE(I7, "%", "")), 0) -> 0 | R7: =IFERROR(VALUE(SUBSTITUTE(J7, "%", "")), 0) -> 0
A8: 4 | B8: 1年 | C8: 0 | D8: =E23 -> 0 | E8: =E27 -> 0.047 | F8: =E31 -> 0.047 | G8: 0 | H8: 0 | I8: 0 | J8: 0 | K8: =IFERROR(VALUE(SUBSTITUTE(C8, "%", "")), 0) -> 0 | L8: =IFERROR(VALUE(SUBSTITUTE(D8, "%", "")), 0) -> 0 | M8: =IFERROR(VALUE(SUBSTITUTE(E8, "%", "")), 0) -> 0.047 | N8: =IFERROR(VALUE(SUBSTITUTE(F8, "%", "")), 0) -> 0.047 | O8: =IFERROR(VALUE(SUBSTITUTE(G8, "%", "")), 0) -> 0 | P8: =IFERROR(VALUE(SUBSTITUTE(H8, "%", "")), 0) -> 0 | Q8: =IFERROR(VALUE(SUBSTITUTE(I8, "%", "")), 0) -> 0 | R8: =IFERROR(VALUE(SUBSTITUTE(J8, "%", "")), 0) -> 0
A9: 4 | B9: 6ヶ月 | C9: 0 | D9: =E24 -> 0 | E9: =E28 -> 0 | F9: =E32 -> 0 | G9: 0 | H9: 0 | I9: 0 | J9: 0 | K9: =IFERROR(VALUE(SUBSTITUTE(C9, "%", "")), 0) -> 0 | L9: =IFERROR(VALUE(SUBSTITUTE(D9, "%", "")), 0) -> 0 | M9: =IFERROR(VALUE(SUBSTITUTE(E9, "%", "")), 0) -> 0 | N9: =IFERROR(VALUE(SUBSTITUTE(F9, "%", "")), 0) -> 0 | O9: =IFERROR(VALUE(SUBSTITUTE(G9, "%", "")), 0) -> 0 | P9: =IFERROR(VALUE(SUBSTITUTE(H9, "%", "")), 0) -> 0 | Q9: =IFERROR(VALUE(SUBSTITUTE(I9, "%", "")), 0) -> 0 | R9: =IFERROR(VALUE(SUBSTITUTE(J9, "%", "")), 0) -> 0
A10: 5 | B10: 1年 | C10: 0 | D10: =F23 -> 0 | E10: =F27 -> 0.056 | F10: =F31 -> 0.083 | G10: 0 | H10: 0 | I10: 0 | J10: 0 | K10: =IFERROR(VALUE(SUBSTITUTE(C10, "%", "")), 0) -> 0 | L10: =IFERROR(VALUE(SUBSTITUTE(D10, "%", "")), 0) -> 0 | M10: =IFERROR(VALUE(SUBSTITUTE(E10, "%", "")), 0) -> 0.056 | N10: =IFERROR(VALUE(SUBSTITUTE(F10, "%", "")), 0) -> 0.083 | O10: =IFERROR(VALUE(SUBSTITUTE(G10, "%", "")), 0) -> 0 | P10: =IFERROR(VALUE(SUBSTITUTE(H10, "%", "")), 0) -> 0 | Q10: =IFERROR(VALUE(SUBSTITUTE(I10, "%", "")), 0) -> 0 | R10: =IFERROR(VALUE(SUBSTITUTE(J10, "%", "")), 0) -> 0
A11: 5 | B11: 6ヶ月 | C11: 0 | D11: =F24 -> 0 | E11: =F28 -> 0.053 | F11: =F32 -> 0.105 | G11: 0 | H11: 0 | I11: 0 | J11: 0 | K11: =IFERROR(VALUE(SUBSTITUTE(C11, "%", "")), 0) -> 0 | L11: =IFERROR(VALUE(SUBSTITUTE(D11, "%", "")), 0) -> 0 | M11: =IFERROR(VALUE(SUBSTITUTE(E11, "%", "")), 0) -> 0.053 | N11: =IFERROR(VALUE(SUBSTITUTE(F11, "%", "")), 0) -> 0.105 | O11: =IFERROR(VALUE(SUBSTITUTE(G11, "%", "")), 0) -> 0 | P11: =IFERROR(VALUE(SUBSTITUTE(H11, "%", "")), 0) -> 0 | Q11: =IFERROR(VALUE(SUBSTITUTE(I11, "%", "")), 0) -> 0 | R11: =IFERROR(VALUE(SUBSTITUTE(J11, "%", "")), 0) -> 0
A12: 6 | B12: 1年 | C12: 0 | D12: =G23 -> 0 | E12: =G27 -> 0 | F12: =G31 -> 0 | G12: 0 | H12: 0 | I12: 0 | J12: 0 | K12: =IFERROR(VALUE(SUBSTITUTE(C12, "%", "")), 0) -> 0 | L12: =IFERROR(VALUE(SUBSTITUTE(D12, "%", "")), 0) -> 0 | M12: =IFERROR(VALUE(SUBSTITUTE(E12, "%", "")), 0) -> 0 | N12: =IFERROR(VALUE(SUBSTITUTE(F12, "%", "")), 0) -> 0 | O12: =IFERROR(VALUE(SUBSTITUTE(G12, "%", "")), 0) -> 0 | P12: =IFERROR(VALUE(SUBSTITUTE(H12, "%", "")), 0) -> 0 | Q12: =IFERROR(VALUE(SUBSTITUTE(I12, "%", "")), 0) -> 0 | R12: =IFERROR(VALUE(SUBSTITUTE(J12, "%", "")), 0) -> 0
A13: 6 | B13: 6ヶ月 | C13: 0 | D13: =G24 -> 0 | E13: =G28 -> 0 | F13: =G32 -> 0 | G13: 0 | H13: 0 | I13: 0 | J13: 0 | K13: =IFERROR(VALUE(SUBSTITUTE(C13, "%", "")), 0) -> 0 | L13: =IFERROR(VALUE(SUBSTITUTE(D13, "%", "")), 0) -> 0 | M13: =IFERROR(VALUE(SUBSTITUTE(E13, "%", "")), 0) -> 0 | N13: =IFERROR(VALUE(SUBSTITUTE(F13, "%", "")), 0) -> 0 | O13: =IFERROR(VALUE(SUBSTITUTE(G13, "%", "")), 0) -> 0 | P13: =IFERROR(VALUE(SUBSTITUTE(H13, "%", "")), 0) -> 0 | Q13: =IFERROR(VALUE(SUBSTITUTE(I13, "%", "")), 0) -> 0 | R13: =IFERROR(VALUE(SUBSTITUTE(J13, "%", "")), 0) -> 0
A16: ※1段目の元ネタをここに張り付ける
A17: 決まり手(総合)
A18: 上:直近1年 | 下:直近6ヶ月
A19: 逃げ | C19: 逃し
A20: 0.458 | C20: 0.5
A21: 0.563 | C21: 0.524
A22: 差され | C22: 差し
A23: 0.186 | C23: 0.175 | D23: 0.033 | E23: 0 | F23: 0 | G23: 0
A24: 0.156 | C24: 0.095 | D24: 0.071 | E24: 0 | F24: 0 | G24: 0
A25: 捲られ | C25: 捲り
A27: 0.288 | C27: 0.05 | D27: 0.067 | E27: 0.047 | F27: 0.056 | G27: 0
A28: 0.25 | C28: 0.048 | D28: 0.071 | E28: 0 | F28: 0.053 | G28: 0
A29: 捲られ差 | C29: 捲り差し
A31: 0.017 | C31: 0 | D31: 0.067 | E31: 0.047 | F31: 0.083 | G31: 0
A32: 0.031 | C32: 0 | D32: 0.071 | E32: 0 | F32: 0.105 | G32: 0

Sheet Sheet2
B2: A列 | C2: 枠
B3: B列 | C3: 期間
B4: C列 | C4: 逃げ
B5: D列 | C5: 差し
B6: E列 | C6: まくり
B7: F列 | C7: まくり差し
B8: G列 | C8: 逃し
B9: H列 | C9: 差され
B10: I列 | C10: 捲られ
B11: J列 | C11: 捲られ差

Sheet TENJI
A1: 艇番 | B1: 展示タイム | C1: ST | D1: 周回 | E1: 周り足 | F1: 直線 | G1: 展示タイム場平均差 | H1: 展示タイム評価(1〜5) | I1: ST評価(1〜5) | J1: 周回評価(1〜5) | K1: 周り足評価(1〜5) | L1: 直線評価(1〜5) | M1: 展示足トータル | N1: 展示攻めポテンシャル | O1: 展示安定感 | P1: 展示補正スコア | Q1: 展示総合スコア | R1: 展示タイプ補正 | S1: 展示タイプ名 | T1: 展開キー | U1: 展開もらい補正 | V1: 最終二次予想スコア
A2: 1 | B2: =B15 -> 6.85 | C2: =VALUE(SUBSTITUTE(B16, "F", "-0")) -> 0.06 | D2: =B17 -> 0 | E2: =B18 -> 6 | F2: =B19 -> 7.13 | G2: =B2-MASTER!$E$3 -> 0.076219512 | H2: =IF(G2<=-0.1, 5, IF(G2<=-0.05, 4, IF(G2<=0.05, 3, IF(G2<=0.1, 2, 1)))) -> 2 | I2: =IF(C2<=-0.05, 1, IF(C2<0, 2, IF(C2<=0.05, 5, IF(C2<=0.12, 4, IF(C2<=0.2, 2, 1))))) -> 4 | J2: =IF(D2-$J$8<=-0.3, 5, IF(D2-$J$8<=-0.1, 4, IF(D2-$J$8<=0.1, 3, IF(D2-$J$8<=0.3, 2, 1)))) -> 3 | K2: =IF(E2-$K$8<=-0.2, 5, IF(E2-$K$8<=-0.05, 4, IF(E2-$K$8<=0.05, 3, IF(E2-$K$8<=0.2, 2, 1)))) -> 1 | L2: =IF(F2-$L$8<=-0.04, 5, IF(F2-$L$8<=-0.01, 4, IF(F2-$L$8<=0.01, 3, IF(F2-$L$8<=0.04, 2, 1)))) -> 2 | M2: =H2 + J2 + K2 + L2 -> 8 | N2: =I2 + L2 -> 6 | O2: =J2 + K2 -> 4 | P2: =M2 - INPUT!R2 -> -0.605 | Q2: =M2 + N2 + O2 -> 18 | R2: {=_xlfn.IFS( AND(A2=1, S2="超伸び型"), 3, AND(A2=1, S2="バランス"), 1, AND(A2=4, S2="超伸び型"), 4, AND(A2>=2, S2="超伸び型"), 3, S2="差し型", 2, S2="攻め型", 2, TRUE, 0 )} -> 1 | S2: {=_xlfn.IFS( L2=5, "超伸び型", AND(N2 >= O2 + 2, H2 >= 4), "攻め型", AND(O2 >= N2 + 2, K2 >= 4), "差し型", H2=5, "伸び型", TRUE, "バランス" )} -> バランス | T2: =IF(OR(S2="超伸び型", S2="攻め型"), IF(L2 = _xlfn.MAXIFS($L$2:$L$7, $S$2:$S$7, S2), 1, 0), 0) -> 0 | U2: =IF( COUNTIF($T$2:$T$7,1)>0, IF( OR( A2 = INDEX($A$2:$A$7, MATCH(1,$T$2:$T$7,0)) - 1, A2 = INDEX($A$2:$A$7, MATCH(1,$T$2:$T$7,0)) + 1 ), 1, 0 ), IF( OR( A2 = INDEX($A$2:$A$7, MATCH(MAX($N$2:$N$7),$N$2:$N$7,0)) - 1, A2 = INDEX($A$2:$A$7, MATCH(MAX($N$2:$N$7),$N$2:$N$7,0)) + 1 ), 1, 0 ) ) -> 0 | V2: =Q2 + R2 + U2 -> 19
A3: 2 | B3: =C15 -> 6.96 | C3: =VALUE(SUBSTITUTE(C16, "F", "-0")) -> 0.03 | D3: =C17 -> 0 | E3: =C18 -> 5.6 | F3: =C19 -> 7.1 | G3: =B3-MASTER!$E$3 -> 0.18621951 | H3: =IF(G3<=-0.1, 5, IF(G3<=-0.05, 4, IF(G3<=0.05, 3, IF(G3<=0.1, 2, 1)))) -> 1 | I3: =IF(C3<=-0.05, 1, IF(C3<0, 2, IF(C3<=0.05, 5, IF(C3<=0.12, 4, IF(C3<=0.2, 2, 1))))) -> 5 | J3: =IF(D3-$J$8<=-0.3, 5, IF(D3-$J$8<=-0.1, 4, IF(D3-$J$8<=0.1, 3, IF(D3-$J$8<=0.3, 2, 1)))) -> 3 | K3: =IF(E3-$K$8<=-0.2, 5, IF(E3-$K$8<=-0.05, 4, IF(E3-$K$8<=0.05, 3, IF(E3-$K$8<=0.2, 2, 1)))) -> 4 | L3: =IF(F3-$L$8<=-0.04, 5, IF(F3-$L$8<=-0.01, 4, IF(F3-$L$8<=0.01, 3, IF(F3-$L$8<=0.04, 2, 1)))) -> 4 | M3: =H3 + J3 + K3 + L3 -> 12 | N3: =I3 + L3 -> 9 | O3: =J3 + K3 -> 7 | P3: =M3 - INPUT!R3 -> 8.9175 | Q3: =M3 + N3 + O3 -> 28 | R3: {=_xlfn.IFS( AND(A3=1, S3="超伸び型"), 3, AND(A3=1, S3="バランス"), 1, AND(A3=4, S3="超伸び型"), 4, AND(A3>=2, S3="超伸び型"), 3, S3="差し型", 2, S3="攻め型", 2, TRUE, 0 )} -> 0 | S3: {=_xlfn.IFS( L3=5, "超伸び型", AND(N3 >= O3 + 2, H3 >= 4), "攻め型", AND(O3 >= N3 + 2, K3 >= 4), "差し型", H3=5, "伸び型", TRUE, "バランス" )} -> バランス | T3: =IF(OR(S3="超伸び型", S3="攻め型"), IF(L3 = _xlfn.MAXIFS($L$2:$L$7, $S$2:$S$7, S3), 1, 0), 0) -> 0 | U3: =IF( COUNTIF($T$2:$T$7,1)>0, IF( OR( A3 = INDEX($A$2:$A$7, MATCH(1,$T$2:$T$7,0)) - 1, A3 = INDEX($A$2:$A$7, MATCH(1,$T$2:$T$7,0)) + 1 ), 1, 0 ), IF( OR( A3 = INDEX($A$2:$A$7, MATCH(MAX($N$2:$N$7),$N$2:$N$7,0)) - 1, A3 = INDEX($A$2:$A$7, MATCH(MAX($N$2:$N$7),$N$2:$N$7,0)) + 1 ), 1, 0 ) ) -> 0 | V3: =Q3 + R3 + U3 -> 28
A4: 3 | B4: =D15 -> 6.98 | C4: =VALUE(SUBSTITUTE(D16, "F", "-0")) -> 0.02 | D4: =D17 -> 0 | E4: =D18 -> 5.63 | F4: =D19 -> 7.13 | G4: =B4-MASTER!$E$3 -> 0.20621951 | H4: =IF(G4<=-0.1, 5, IF(G4<=-0.05, 4, IF(G4<=0.05, 3, IF(G4<=0.1, 2, 1)))) -> 1 | I4: =IF(C4<=-0.05, 1, IF(C4<0, 2, IF(C4<=0.05, 5, IF(C4<=0.12, 4, IF(C4<=0.2, 2, 1))))) -> 5 | J4: =IF(D4-$J$8<=-0.3, 5, IF(D4-$J$8<=-0.1, 4, IF(D4-$J$8<=0.1, 3, IF(D4-$J$8<=0.3, 2, 1)))) -> 3 | K4: =IF(E4-$K$8<=-0.2, 5, IF(E4-$K$8<=-0.05, 4, IF(E4-$K$8<=0.05, 3, IF(E4-$K$8<=0.2, 2, 1)))) -> 4 | L4: =IF(F4-$L$8<=-0.04, 5, IF(F4-$L$8<=-0.01, 4, IF(F4-$L$8<=0.01, 3, IF(F4-$L$8<=0.04, 2, 1)))) -> 2 | M4: =H4 + J4 + K4 + L4 -> 10 | N4: =I4 + L4 -> 7 | O4: =J4 + K4 -> 7 | P4: =M4 - INPUT!R4 -> 6.6175 | Q4: =M4 + N4 + O4 -> 24 | R4: {=_xlfn.IFS( AND(A4=1, S4="超伸び型"), 3, AND(A4=1, S4="バランス"), 1, AND(A4=4, S4="超伸び型"), 4, AND(A4>=2, S4="超伸び型"), 3, S4="差し型", 2, S4="攻め型", 2, TRUE, 0 )} -> 0 | S4: {=_xlfn.IFS( L4=5, "超伸び型", AND(N4 >= O4 + 2, H4 >= 4), "攻め型", AND(O4 >= N4 + 2, K4 >= 4), "差し型", H4=5, "伸び型", TRUE, "バランス" )} -> バランス | T4: =IF(OR(S4="超伸び型", S4="攻め型"), IF(L4 = _xlfn.MAXIFS($L$2:$L$7, $S$2:$S$7, S4), 1, 0), 0) -> 0 | U4: =IF( COUNTIF($T$2:$T$7,1)>0, IF( OR( A4 = INDEX($A$2:$A$7, MATCH(1,$T$2:$T$7,0)) - 1, A4 = INDEX($A$2:$A$7, MATCH(1,$T$2:$T$7,0)) + 1 ), 1, 0 ), IF( OR( A4 = INDEX($A$2:$A$7, MATCH(MAX($N$2:$N$7),$N$2:$N$7,0)) - 1, A4 = INDEX($A$2:$A$7, MATCH(MAX($N$2:$N$7),$N$2:$N$7,0)) + 1 ), 1, 0 ) ) -> 1 | V4: =Q4 + R4 + U4 -> 25
A5: 4 | B5: =E15 -> 6.93 | C5: =VALUE(SUBSTITUTE(E16, "F", "-0")) -> -0.02 | D5: =E17 -> 0 | E5: =E18 -> 5.73 | F5: =E19 -> 7.07 | G5: =B5-MASTER!$E$3 -> 0.15621951 | H5: =IF(G5<=-0.1, 5, IF(G5<=-0.05, 4, IF(G5<=0.05, 3, IF(G5<=0.1, 2, 1)))) -> 1 | I5: =IF(C5<=-0.05, 1, IF(C5<0, 2, IF(C5<=0.05, 5, IF(C5<=0.12, 4, IF(C5<=0.2, 2, 1))))) -> 2 | J5: =IF(D5-$J$8<=-0.3, 5, IF(D5-$J$8<=-0.1, 4, IF(D5-$J$8<=0.1, 3, IF(D5-$J$8<=0.3, 2, 1)))) -> 3 | K5: =IF(E5-$K$8<=-0.2, 5, IF(E5-$K$8<=-0.05, 4, IF(E5-$K$8<=0.05, 3, IF(E5-$K$8<=0.2, 2, 1)))) -> 3 | L5: =IF(F5-$L$8<=-0.04, 5, IF(F5-$L$8<=-0.01, 4, IF(F5-$L$8<=0.01, 3, IF(F5-$L$8<=0.04, 2, 1)))) -> 5 | M5: =H5 + J5 + K5 + L5 -> 12 | N5: =I5 + L5 -> 7 | O5: =J5 + K5 -> 6 | P5: =M5 - INPUT!R5 -> 9.035 | Q5: =M5 + N5 + O5 -> 25 | R5: {=_xlfn.IFS( AND(A5=1, S5="超伸び型"), 3, AND(A5=1, S5="バランス"), 1, AND(A5=4, S5="超伸び型"), 4, AND(A5>=2, S5="超伸び型"), 3, S5="差し型", 2, S5="攻め型", 2, TRUE, 0 )} -> 4 | S5: {=_xlfn.IFS( L5=5, "超伸び型", AND(N5 >= O5 + 2, H5 >= 4), "攻め型", AND(O5 >= N5 + 2, K5 >= 4), "差し型", H5=5, "伸び型", TRUE, "バランス" )} -> 超伸び型 | T5: =IF(OR(S5="超伸び型", S5="攻め型"), IF(L5 = _xlfn.MAXIFS($L$2:$L$7, $S$2:$S$7, S5), 1, 0), 0) -> 1 | U5: =IF( COUNTIF($T$2:$T$7,1)>0, IF( OR( A5 = INDEX($A$2:$A$7, MATCH(1,$T$2:$T$7,0)) - 1, A5 = INDEX($A$2:$A$7, MATCH(1,$T$2:$T$7,0)) + 1 ), 1, 0 ), IF( OR( A5 = INDEX($A$2:$A$7, MATCH(MAX($N$2:$N$7),$N$2:$N$7,0)) - 1, A5 = INDEX($A$2:$A$7, MATCH(MAX($N$2:$N$7),$N$2:$N$7,0)) + 1 ), 1, 0 ) ) -> 0 | V5: =Q5 + R5 + U5 -> 29
A6: 5 | B6: =F15 -> 6.92 | C6: =VALUE(SUBSTITUTE(F16, "F", "-0")) -> 0.01 | D6: =F17 -> 0 | E6: =F18 -> 5.83 | F6: =F19 -> 7.11 | G6: =B6-MASTER!$E$3 -> 0.14621951 | H6: =IF(G6<=-0.1, 5, IF(G6<=-0.05, 4, IF(G6<=0.05, 3, IF(G6<=0.1, 2, 1)))) -> 1 | I6: =IF(C6<=-0.05, 1, IF(C6<0, 2, IF(C6<=0.05, 5, IF(C6<=0.12, 4, IF(C6<=0.2, 2, 1))))) -> 5 | J6: =IF(D6-$J$8<=-0.3, 5, IF(D6-$J$8<=-0.1, 4, IF(D6-$J$8<=0.1, 3, IF(D6-$J$8<=0.3, 2, 1)))) -> 3 | K6: =IF(E6-$K$8<=-0.2, 5, IF(E6-$K$8<=-0.05, 4, IF(E6-$K$8<=0.05, 3, IF(E6-$K$8<=0.2, 2, 1)))) -> 2 | L6: =IF(F6-$L$8<=-0.04, 5, IF(F6-$L$8<=-0.01, 4, IF(F6-$L$8<=0.01, 3, IF(F6-$L$8<=0.04, 2, 1)))) -> 3 | M6: =H6 + J6 + K6 + L6 -> 9 | N6: =I6 + L6 -> 8 | O6: =J6 + K6 -> 5 | P6: =M6 - INPUT!R6 -> 4.3275 | Q6: =M6 + N6 + O6 -> 22 | R6: {=_xlfn.IFS( AND(A6=1, S6="超伸び型"), 3, AND(A6=1, S6="バランス"), 1, AND(A6=4, S6="超伸び型"), 4, AND(A6>=2, S6="超伸び型"), 3, S6="差し型", 2, S6="攻め型", 2, TRUE, 0 )} -> 0 | S6: {=_xlfn.IFS( L6=5, "超伸び型", AND(N6 >= O6 + 2, H6 >= 4), "攻め型", AND(O6 >= N6 + 2, K6 >= 4), "差し型", H6=5, "伸び型", TRUE, "バランス" )} -> バランス | T6: =IF(OR(S6="超伸び型", S6="攻め型"), IF(L6 = _xlfn.MAXIFS($L$2:$L$7, $S$2:$S$7, S6), 1, 0), 0) -> 0 | U6: =IF( COUNTIF($T$2:$T$7,1)>0, IF( OR( A6 = INDEX($A$2:$A$7, MATCH(1,$T$2:$T$7,0)) - 1, A6 = INDEX($A$2:$A$7, MATCH(1,$T$2:$T$7,0)) + 1 ), 1, 0 ), IF( OR( A6 = INDEX($A$2:$A$7, MATCH(MAX($N$2:$N$7),$N$2:$N$7,0)) - 1, A6 = INDEX($A$2:$A$7, MATCH(MAX($N$2:$N$7),$N$2:$N$7,0)) + 1 ), 1, 0 ) ) -> 1 | V6: =Q6 + R6 + U6 -> 23
A7: 6 | B7: =G15 -> 6.9 | C7: =VALUE(SUBSTITUTE(G16, "F", "-0")) -> 0.07 | D7: =G17 -> 0 | E7: =G18 -> 5.73 | F7: =G19 -> 7.13 | G7: =B7-MASTER!$E$3 -> 0.12621951 | H7: =IF(G7<=-0.1, 5, IF(G7<=-0.05, 4, IF(G7<=0.05, 3, IF(G7<=0.1, 2, 1)))) -> 1 | I7: =IF(C7<=-0.05, 1, IF(C7<0, 2, IF(C7<=0.05, 5, IF(C7<=0.12, 4, IF(C7<=0.2, 2, 1))))) -> 4 | J7: =IF(D7-$J$8<=-0.3, 5, IF(D7-$J$8<=-0.1, 4, IF(D7-$J$8<=0.1, 3, IF(D7-$J$8<=0.3, 2, 1)))) -> 3 | K7: =IF(E7-$K$8<=-0.2, 5, IF(E7-$K$8<=-0.05, 4, IF(E7-$K$8<=0.05, 3, IF(E7-$K$8<=0.2, 2, 1)))) -> 3 | L7: =IF(F7-$L$8<=-0.04, 5, IF(F7-$L$8<=-0.01, 4, IF(F7-$L$8<=0.01, 3, IF(F7-$L$8<=0.04, 2, 1)))) -> 2 | M7: =H7 + J7 + K7 + L7 -> 9 | N7: =I7 + L7 -> 6 | O7: =J7 + K7 -> 6 | P7: =M7 - INPUT!R7 -> 5.7325 | Q7: =M7 + N7 + O7 -> 21 | R7: {=_xlfn.IFS( AND(A7=1, S7="超伸び型"), 3, AND(A7=1, S7="バランス"), 1, AND(A7=4, S7="超伸び型"), 4, AND(A7>=2, S7="超伸び型"), 3, S7="差し型", 2, S7="攻め型", 2, TRUE, 0 )} -> 0 | S7: {=_xlfn.IFS( L7=5, "超伸び型", AND(N7 >= O7 + 2, H7 >= 4), "攻め型", AND(O7 >= N7 + 2, K7 >= 4), "差し型", H7=5, "伸び型", TRUE, "バランス" )} -> バランス | T7: =IF(OR(S7="超伸び型", S7="攻め型"), IF(L7 = _xlfn.MAXIFS($L$2:$L$7, $S$2:$S$7, S7), 1, 0), 0) -> 0 | U7: =IF( COUNTIF($T$2:$T$7,1)>0, IF( OR( A7 = INDEX($A$2:$A$7, MATCH(1,$T$2:$T$7,0)) - 1, A7 = INDEX($A$2:$A$7, MATCH(1,$T$2:$T$7,0)) + 1 ), 1, 0 ), IF( OR( A7 = INDEX($A$2:$A$7, MATCH(MAX($N$2:$N$7),$N$2:$N$7,0)) - 1, A7 = INDEX($A$2:$A$7, MATCH(MAX($N$2:$N$7),$N$2:$N$7,0)) + 1 ), 1, 0 ) ) -> 0 | V7: =Q7 + R7 + U7 -> 21
I8: 6艇平均 | J8: =AVERAGE(D$2:D$7) -> 0 | K8: =AVERAGE(E$2:E$7) -> 5.7533333 | L8: =AVERAGE(F$2:F$7) -> 7.1116667
A11: 展示情報
A12: 直前情報
A13: 展示情報
A14: 進入 | B14: 1 | C14: 2 | D14: 3 | E14: 4 | F14: 5 | G14: 6
A15: 展示 | B15: 6.85 | C15: 6.96 | D15: 6.98 | E15: 6.93 | F15: 6.92 | G15: 6.9
A16: ST | B16: 0.06 | C16: 0.03 | D16: 0.02 | E16: F.02 | F16: 0.01 | G16: 0.07
A17: 周回 | B17: 0 | C17: 0 | D17: 0 | E17: 0 | F17: 0 | G17: 0
A18: 周り足 | B18: 6 | C18: 5.6 | D18: 5.63 | E18: 5.73 | F18: 5.83 | G18: 5.73
A19: 直線 | B19: 7.13 | C19: 7.1 | D19: 7.13 | E19: 7.07 | F19: 7.11 | G19: 7.13

Sheet TENJI (2)
A1: 艇番 | B1: 展示タイム | C1: ST | D1: 周回 | E1: 周り足 | F1: 直線 | G1: 展示タイム場平均差 | H1: 展示タイム評価(1〜5) | I1: ST評価(1〜5) | J1: 周回評価(1〜5) | K1: 周り足評価(1〜5) | L1: 直線評価(1〜5) | M1: 展示足トータル | N1: 展示攻めポテンシャル | O1: 展示安定感 | P1: 展示補正スコア | Q1: 展示総合スコア | R1: 展示タイプ補正 | S1: 展示タイプ名 | T1: 展開キー | U1: 展開もらい補正 | V1: 最終二次予想スコア
A2: 1 | B2: =B15 -> 6.85 | C2: =VALUE(SUBSTITUTE(B16, "F", "-0")) -> 0.06 | D2: =B17 -> 0 | E2: =B18 -> 6 | F2: =B19 -> 7.13 | G2: =B2-MASTER!$E$3 -> 0.076219512 | H2: =IF(G2<=-0.1, 5, IF(G2<=-0.05, 4, IF(G2<=0.05, 3, IF(G2<=0.1, 2, 1)))) | I2: =IF(C2<=-0.05, 1, IF(C2<0, 2, IF(C2<=0.05, 5, IF(C2<=0.12, 4, IF(C2<=0.2, 2, 1))))) | J2: =IF(D2-$J$8<=-0.3, 5, IF(D2-$J$8<=-0.1, 4, IF(D2-$J$8<=0.1, 3, IF(D2-$J$8<=0.3, 2, 1)))) | K2: =IF(E2-$K$8<=-0.2, 5, IF(E2-$K$8<=-0.05, 4, IF(E2-$K$8<=0.05, 3, IF(E2-$K$8<=0.2, 2, 1)))) | L2: =IF(F2-$L$8<=-0.04, 5, IF(F2-$L$8<=-0.01, 4, IF(F2-$L$8<=0.01, 3, IF(F2-$L$8<=0.04, 2, 1)))) | M2: =H2 + J2 + K2 + L2 | N2: =I2 + L2 | O2: =J2 + K2 | P2: =M2 - INPUT!R2 | Q2: =M2 + N2 + O2 | R2: =IFS( AND(A2=1, S2="超伸び型"), 3, AND(A2=1, S2="バランス"), 1, AND(A2=4, S2="超伸び型"), 4, AND(A2>=2, S2="超伸び型"), 3, S2="差し型", 2, S2="攻め型", 2, TRUE, 0 ) | S2: =IFS( L2=5, "超伸び型", AND(N2 >= O2 + 2, H2 >= 4), "攻め型", AND(O2 >= N2 + 2, K2 >= 4), "差し型", H2=5, "伸び型", TRUE, "バランス" ) | T2: =IF(OR(S2="超伸び型", S2="攻め型"), IF(L2 = MAXIFS($L$2:$L$7, $S$2:$S$7, S2), 1, 0), 0) | U2: =IF( COUNTIF($T$2:$T$7,1)>0, IF( OR( A2 = INDEX($A$2:$A$7, MATCH(1,$T$2:$T$7,0)) - 1, A2 = INDEX($A$2:$A$7, MATCH(1,$T$2:$T$7,0)) + 1 ), 1, 0 ), IF( OR( A2 = INDEX($A$2:$A$7, MATCH(MAX($N$2:$N$7),$N$2:$N$7,0)) - 1, A2 = INDEX($A$2:$A$7, MATCH(MAX($N$2:$N$7),$N$2:$N$7,0)) + 1 ), 1, 0 ) ) | V2: =Q2 + R2 + U2
A3: 2 | B3: =C15 -> 6.96 | C3: =VALUE(SUBSTITUTE(C16, "F", "-0")) -> 0.03 | D3: =C17 -> 0 | E3: =C18 -> 5.6 | F3: =C19 -> 7.1 | G3: =B3-MASTER!$E$3 -> 0.18621951 | H3: =IF(G3<=-0.1, 5, IF(G3<=-0.05, 4, IF(G3<=0.05, 3, IF(G3<=0.1, 2, 1)))) | I3: =IF(C3<=-0.05, 1, IF(C3<0, 2, IF(C3<=0.05, 5, IF(C3<=0.12, 4, IF(C3<=0.2, 2, 1))))) | J3: =IF(D3-$J$8<=-0.3, 5, IF(D3-$J$8<=-0.1, 4, IF(D3-$J$8<=0.1, 3, IF(D3-$J$8<=0.3, 2, 1)))) | K3: =IF(E3-$K$8<=-0.2, 5, IF(E3-$K$8<=-0.05, 4, IF(E3-$K$8<=0.05, 3, IF(E3-$K$8<=0.2, 2, 1)))) | L3: =IF(F3-$L$8<=-0.04, 5, IF(F3-$L$8<=-0.01, 4, IF(F3-$L$8<=0.01, 3, IF(F3-$L$8<=0.04, 2, 1)))) | M3: =H3 + J3 + K3 + L3 | N3: =I3 + L3 | O3: =J3 + K3 | P3: =M3 - INPUT!R3 | Q3: =M3 + N3 + O3 | R3: =IFS( AND(A3=1, S3="超伸び型"), 3, AND(A3=1, S3="バランス"), 1, AND(A3=4, S3="超伸び型"), 4, AND(A3>=2, S3="超伸び型"), 3, S3="差し型", 2, S3="攻め型", 2, TRUE, 0 ) | S3: =IFS( L3=5, "超伸び型", AND(N3 >= O3 + 2, H3 >= 4), "攻め型", AND(O3 >= N3 + 2, K3 >= 4), "差し型", H3=5, "伸び型", TRUE, "バランス" ) | T3: =IF(OR(S3="超伸び型", S3="攻め型"), IF(L3 = MAXIFS($L$2:$L$7, $S$2:$S$7, S3), 1, 0), 0) | U3: =IF( COUNTIF($T$2:$T$7,1)>0, IF( OR( A3 = INDEX($A$2:$A$7, MATCH(1,$T$2:$T$7,0)) - 1, A3 = INDEX($A$2:$A$7, MATCH(1,$T$2:$T$7,0)) + 1 ), 1, 0 ), IF( OR( A3 = INDEX($A$2:$A$7, MATCH(MAX($N$2:$N$7),$N$2:$N$7,0)) - 1, A3 = INDEX($A$2:$A$7, MATCH(MAX($N$2:$N$7),$N$2:$N$7,0)) + 1 ), 1, 0 ) ) | V3: =Q3 + R3 + U3
A4: 3 | B4: =D15 -> 6.98 | C4: =VALUE(SUBSTITUTE(D16, "F", "-0")) -> 0.02 | D4: =D17 -> 0 | E4: =D18 -> 5.63 | F4: =D19 -> 7.13 | G4: =B4-MASTER!$E$3 -> 0.20621951 | H4: =IF(G4<=-0.1, 5, IF(G4<=-0.05, 4, IF(G4<=0.05, 3, IF(G4<=0.1, 2, 1)))) | I4: =IF(C4<=-0.05, 1, IF(C4<0, 2, IF(C4<=0.05, 5, IF(C4<=0.12, 4, IF(C4<=0.2, 2, 1))))) | J4: =IF(D4-$J$8<=-0.3, 5, IF(D4-$J$8<=-0.1, 4, IF(D4-$J$8<=0.1, 3, IF(D4-$J$8<=0.3, 2, 1)))) | K4: =IF(E4-$K$8<=-0.2, 5, IF(E4-$K$8<=-0.05, 4, IF(E4-$K$8<=0.05, 3, IF(E4-$K$8<=0.2, 2, 1)))) | L4: =IF(F4-$L$8<=-0.04, 5, IF(F4-$L$8<=-0.01, 4, IF(F4-$L$8<=0.01, 3, IF(F4-$L$8<=0.04, 2, 1)))) | M4: =H4 + J4 + K4 + L4 | N4: =I4 + L4 | O4: =J4 + K4 | P4: =M4 - INPUT!R4 | Q4: =M4 + N4 + O4 | R4: =IFS( AND(A4=1, S4="超伸び型"), 3, AND(A4=1, S4="バランス"), 1, AND(A4=4, S4="超伸び型"), 4, AND(A4>=2, S4="超伸び型"), 3, S4="差し型", 2, S4="攻め型", 2, TRUE, 0 ) | S4: =IFS( L4=5, "超伸び型", AND(N4 >= O4 + 2, H4 >= 4), "攻め型", AND(O4 >= N4 + 2, K4 >= 4), "差し型", H4=5, "伸び型", TRUE, "バランス" ) | T4: =IF(OR(S4="超伸び型", S4="攻め型"), IF(L4 = MAXIFS($L$2:$L$7, $S$2:$S$7, S4), 1, 0), 0) | U4: =IF( COUNTIF($T$2:$T$7,1)>0, IF( OR( A4 = INDEX($A$2:$A$7, MATCH(1,$T$2:$T$7,0)) - 1, A4 = INDEX($A$2:$A$7, MATCH(1,$T$2:$T$7,0)) + 1 ), 1, 0 ), IF( OR( A4 = INDEX($A$2:$A$7, MATCH(MAX($N$2:$N$7),$N$2:$N$7,0)) - 1, A4 = INDEX($A$2:$A$7, MATCH(MAX($N$2:$N$7),$N$2:$N$7,0)) + 1 ), 1, 0 ) ) | V4: =Q4 + R4 + U4
A5: 4 | B5: =E15 -> 6.93 | C5: =VALUE(SUBSTITUTE(E16, "F", "-0")) -> -0.02 | D5: =E17 -> 0 | E5: =E18 -> 5.73 | F5: =E19 -> 7.07 | G5: =B5-MASTER!$E$3 -> 0.15621951 | H5: =IF(G5<=-0.1, 5, IF(G5<=-0.05, 4, IF(G5<=0.05, 3, IF(G5<=0.1, 2, 1)))) | I5: =IF(C5<=-0.05, 1, IF(C5<0, 2, IF(C5<=0.05, 5, IF(C5<=0.12, 4, IF(C5<=0.2, 2, 1))))) | J5: =IF(D5-$J$8<=-0.3, 5, IF(D5-$J$8<=-0.1, 4, IF(D5-$J$8<=0.1, 3, IF(D5-$J$8<=0.3, 2, 1)))) | K5: =IF(E5-$K$8<=-0.2, 5, IF(E5-$K$8<=-0.05, 4, IF(E5-$K$8<=0.05, 3, IF(E5-$K$8<=0.2, 2, 1)))) | L5: =IF(F5-$L$8<=-0.04, 5, IF(F5-$L$8<=-0.01, 4, IF(F5-$L$8<=0.01, 3, IF(F5-$L$8<=0.04, 2, 1)))) | M5: =H5 + J5 + K5 + L5 | N5: =I5 + L5 | O5: =J5 + K5 | P5: =M5 - INPUT!R5 | Q5: =M5 + N5 + O5 | R5: =IFS( AND(A5=1, S5="超伸び型"), 3, AND(A5=1, S5="バランス"), 1, AND(A5=4, S5="超伸び型"), 4, AND(A5>=2, S5="超伸び型"), 3, S5="差し型", 2, S5="攻め型", 2, TRUE, 0 ) | S5: =IFS( L5=5, "超伸び型", AND(N5 >= O5 + 2, H5 >= 4), "攻め型", AND(O5 >= N5 + 2, K5 >= 4), "差し型", H5=5, "伸び型", TRUE, "バランス" ) | T5: =IF(OR(S5="超伸び型", S5="攻め型"), IF(L5 = MAXIFS($L$2:$L$7, $S$2:$S$7, S5), 1, 0), 0) | U5: =IF( COUNTIF($T$2:$T$7,1)>0, IF( OR( A5 = INDEX($A$2:$A$7, MATCH(1,$T$2:$T$7,0)) - 1, A5 = INDEX($A$2:$A$7, MATCH(1,$T$2:$T$7,0)) + 1 ), 1, 0 ), IF( OR( A5 = INDEX($A$2:$A$7, MATCH(MAX($N$2:$N$7),$N$2:$N$7,0)) - 1, A5 = INDEX($A$2:$A$7, MATCH(MAX($N$2:$N$7),$N$2:$N$7,0)) + 1 ), 1, 0 ) ) | V5: =Q5 + R5 + U5
A6: 5 | B6: =F15 -> 6.92 | C6: =VALUE(SUBSTITUTE(F16, "F", "-0")) -> 0.01 | D6: =F17 -> 0 | E6: =F18 -> 5.83 | F6: =F19 -> 7.11 | G6: =B6-MASTER!$E$3 -> 0.14621951 | H6: =IF(G6<=-0.1, 5, IF(G6<=-0.05, 4, IF(G6<=0.05, 3, IF(G6<=0.1, 2, 1)))) | I6: =IF(C6<=-0.05, 1, IF(C6<0, 2, IF(C6<=0.05, 5, IF(C6<=0.12, 4, IF(C6<=0.2, 2, 1))))) | J6: =IF(D6-$J$8<=-0.3, 5, IF(D6-$J$8<=-0.1, 4, IF(D6-$J$8<=0.1, 3, IF(D6-$J$8<=0.3, 2, 1)))) | K6: =IF(E6-$K$8<=-0.2, 5, IF(E6-$K$8<=-0.05, 4, IF(E6-$K$8<=0.05, 3, IF(E6-$K$8<=0.2, 2, 1)))) | L6: =IF(F6-$L$8<=-0.04, 5, IF(F6-$L$8<=-0.01, 4, IF(F6-$L$8<=0.01, 3, IF(F6-$L$8<=0.04, 2, 1)))) | M6: =H6 + J6 + K6 + L6 | N6: =I6 + L6 | O6: =J6 + K6 | P6: =M6 - INPUT!R6 | Q6: =M6 + N6 + O6 | R6: =IFS( AND(A6=1, S6="超伸び型"), 3, AND(A6=1, S6="バランス"), 1, AND(A6=4, S6="超伸び型"), 4, AND(A6>=2, S6="超伸び型"), 3, S6="差し型", 2, S6="攻め型", 2, TRUE, 0 ) | S6: =IFS( L6=5, "超伸び型", AND(N6 >= O6 + 2, H6 >= 4), "攻め型", AND(O6 >= N6 + 2, K6 >= 4), "差し型", H6=5, "伸び型", TRUE, "バランス" ) | T6: =IF(OR(S6="超伸び型", S6="攻め型"), IF(L6 = MAXIFS($L$2:$L$7, $S$2:$S$7, S6), 1, 0), 0) | U6: =IF( COUNTIF($T$2:$T$7,1)>0, IF( OR( A6 = INDEX($A$2:$A$7, MATCH(1,$T$2:$T$7,0)) - 1, A6 = INDEX($A$2:$A$7, MATCH(1,$T$2:$T$7,0)) + 1 ), 1, 0 ), IF( OR( A6 = INDEX($A$2:$A$7, MATCH(MAX($N$2:$N$7),$N$2:$N$7,0)) - 1, A6 = INDEX($A$2:$A$7, MATCH(MAX($N$2:$N$7),$N$2:$N$7,0)) + 1 ), 1, 0 ) ) | V6: =Q6 + R6 + U6
A7: 6 | B7: =G15 -> 6.9 | C7: =VALUE(SUBSTITUTE(G16, "F", "-0")) -> 0.07 | D7: =G17 -> 0 | E7: =G18 -> 5.73 | F7: =G19 -> 7.13 | G7: =B7-MASTER!$E$3 -> 0.12621951 | H7: =IF(G7<=-0.1, 5, IF(G7<=-0.05, 4, IF(G7<=0.05, 3, IF(G7<=0.1, 2, 1)))) | I7: =IF(C7<=-0.05, 1, IF(C7<0, 2, IF(C7<=0.05, 5, IF(C7<=0.12, 4, IF(C7<=0.2, 2, 1))))) | J7: =IF(D7-$J$8<=-0.3, 5, IF(D7-$J$8<=-0.1, 4, IF(D7-$J$8<=0.1, 3, IF(D7-$J$8<=0.3, 2, 1)))) | K7: =IF(E7-$K$8<=-0.2, 5, IF(E7-$K$8<=-0.05, 4, IF(E7-$K$8<=0.05, 3, IF(E7-$K$8<=0.2, 2, 1)))) | L7: =IF(F7-$L$8<=-0.04, 5, IF(F7-$L$8<=-0.01, 4, IF(F7-$L$8<=0.01, 3, IF(F7-$L$8<=0.04, 2, 1)))) | M7: =H7 + J7 + K7 + L7 | N7: =I7 + L7 | O7: =J7 + K7 | P7: =M7 - INPUT!R7 | Q7: =M7 + N7 + O7 | R7: =IFS( AND(A7=1, S7="超伸び型"), 3, AND(A7=1, S7="バランス"), 1, AND(A7=4, S7="超伸び型"), 4, AND(A7>=2, S7="超伸び型"), 3, S7="差し型", 2, S7="攻め型", 2, TRUE, 0 ) | S7: =IFS( L7=5, "超伸び型", AND(N7 >= O7 + 2, H7 >= 4), "攻め型", AND(O7 >= N7 + 2, K7 >= 4), "差し型", H7=5, "伸び型", TRUE, "バランス" ) | T7: =IF(OR(S7="超伸び型", S7="攻め型"), IF(L7 = MAXIFS($L$2:$L$7, $S$2:$S$7, S7), 1, 0), 0) | U7: =IF( COUNTIF($T$2:$T$7,1)>0, IF( OR( A7 = INDEX($A$2:$A$7, MATCH(1,$T$2:$T$7,0)) - 1, A7 = INDEX($A$2:$A$7, MATCH(1,$T$2:$T$7,0)) + 1 ), 1, 0 ), IF( OR( A7 = INDEX($A$2:$A$7, MATCH(MAX($N$2:$N$7),$N$2:$N$7,0)) - 1, A7 = INDEX($A$2:$A$7, MATCH(MAX($N$2:$N$7),$N$2:$N$7,0)) + 1 ), 1, 0 ) ) | V7: =Q7 + R7 + U7
I8: 6艇平均 | J8: =AVERAGE(D$2:D$7) -> 0 | K8: =AVERAGE(E$2:E$7) -> 5.7533333 | L8: =AVERAGE(F$2:F$7) -> 7.1116667
A11: 展示情報
A12: 直前情報
A13: 展示情報
A14: 進入 | B14: 1 | C14: 2 | D14: 3 | E14: 4 | F14: 5 | G14: 6
A15: 展示 | B15: 6.85 | C15: 6.96 | D15: 6.98 | E15: 6.93 | F15: 6.92 | G15: 6.9
A16: ST | B16: 0.06 | C16: 0.03 | D16: 0.02 | E16: F.02 | F16: 0.01 | G16: 0.07
A17: 周回 | B17: 0 | C17: 0 | D17: 0 | E17: 0 | F17: 0 | G17: 0
A18: 周り足 | B18: 6 | C18: 5.6 | D18: 5.63 | E18: 5.73 | F18: 5.83 | G18: 5.73
A19: 直線 | B19: 7.13 | C19: 7.1 | D19: 7.13 | E19: 7.07 | F19: 7.11 | G19: 7.13

Sheet Sheet5
B1: A~F列が展示情報をそのまま載せる | F1: A～F列は展示情報をそのまま載せる
B2: =CHAR(64+ROW(A1))&"列：" -> A列： | C2: 艇番 | F2: A列：艇番
B3: =CHAR(64+ROW(A2))&"列：" -> B列： | C3: 展示タイム | F3: B列：展示タイム
B4: =CHAR(64+ROW(A3))&"列：" -> C列： | C4: ST | F4: C列：ST
B5: =CHAR(64+ROW(A4))&"列：" -> D列： | C5: 周回 | F5: D列：周回
B6: =CHAR(64+ROW(A5))&"列：" -> E列： | C6: 周り足 | F6: E列：周り足
B7: =CHAR(64+ROW(A6))&"列：" -> F列： | C7: 直線 | F7: F列：直線
B8: G列：～V列は数式を使って算出 | F8: G～V列は数式を使って算出
B9: =CHAR(64+ROW(A9))&"列：" -> I列： | C9: 展示タイム場平均差 | F9: I列：展示タイム場平均差
B10: =CHAR(64+ROW(A10))&"列：" -> J列： | C10: 展示タイム評価(1〜5) | F10: J列：展示タイム評価(1〜5)
B11: =CHAR(64+ROW(A11))&"列：" -> K列： | C11: ST評価(1〜5) | F11: K列：ST評価(1〜5)
B12: =CHAR(64+ROW(A12))&"列：" -> L列： | C12: 周回評価(1〜5) | F12: L列：周回評価(1〜5)
B13: =CHAR(64+ROW(A13))&"列：" -> M列： | C13: 周り足評価(1〜5) | F13: M列：周り足評価(1〜5)
B14: =CHAR(64+ROW(A14))&"列：" -> N列： | C14: 直線評価(1〜5) | F14: N列：直線評価(1〜5)
B15: =CHAR(64+ROW(A15))&"列：" -> O列： | C15: 展示足トータル | F15: O列：展示足トータル
B16: =CHAR(64+ROW(A16))&"列：" -> P列： | C16: 展示攻めポテンシャル | F16: P列：展示攻めポテンシャル
B17: =CHAR(64+ROW(A17))&"列：" -> Q列： | C17: 展示安定感 | F17: Q列：展示安定感
B18: =CHAR(64+ROW(A18))&"列：" -> R列： | C18: 展示補正スコア | F18: R列：展示補正スコア
B19: =CHAR(64+ROW(A19))&"列：" -> S列： | C19: 展示総合スコア | F19: S列：展示総合スコア
B20: =CHAR(64+ROW(A20))&"列：" -> T列： | C20: 展示タイプ補正 | F20: T列：展示タイプ補正
... B24: =CHAR(64+ROW(A24))&"列：" -> X列： | C24: 最終二次予想スコア | F24: X列：最終二次予想スコア

Sheet FORECAST
A1: 艇番 | B1: 枠番 | C1: 直近6ヶ月3連対率 | D1: 直近3ヶ月3連対率 | E1: 展示総合スコア（R） | F1: 展示タイプ名（T） | G1: 展示タイプ補正（S） | H1: 展開キー（U） | I1: 展開もらい補正（V） | J1: 最終二次予想スコア（W） | K1: 逃げ率（6ヶ月） | L1: 差し率（6ヶ月） | M1: まくり率（6ヶ月） | N1: まくり差し率（6ヶ月） | O1: 逃し率（6ヶ月） | P1: 差され率（6ヶ月） | Q1: 捲られ率（6ヶ月） | R1: 捲られ差し率（6ヶ月） | S1: 期待値 | T1: 展開フラグ_差し | U1: 展開フラグ_まくり | V1: 展開フラグ_まくり差し | W1: 展開フラグ_逃し | X1: 決まり手タイプ | Y1: 決まり手補正（X） | Z1: 三次予想スコア | AA1: 切る艇
A2: 1 | B2: 1 | C2: =B12 -> 0.813 | D2: =B14 -> 0.929 | E2: =TENJI!Q2 -> 18 | F2: =TENJI!S2 -> バランス | G2: =TENJI!R2 -> 1 | H2: =TENJI!T2 -> 0 | I2: =TENJI!U2 -> 0 | J2: =TENJI!V2 -> 19 | K2: =KIMARITE!C3 -> 0.563 | L2: =KIMARITE!D3 -> 0 | M2: =KIMARITE!E3 -> 0 | N2: =KIMARITE!F3 -> 0 | O2: =KIMARITE!G3 -> 0 | P2: =KIMARITE!H3 -> 0.156 | Q2: =KIMARITE!I3 -> 0.25 | R2: =KIMARITE!J3 -> 0.031 | S2: =KIMARITE!K2 * (1 + (E2/100)) -> 0.54044 | T2: - | U2: - | V2: - | W2: - | X2: =IF(AND(K2>=0.2, B2=1),"逃げ型", IF(L2>=0.05,"差し型", IF(OR(M2>=0.05, N2>=0.05),"攻め型", IF(OR(P2>=0.2, R2>=0.2),"脆い型", "無色")))) -> 逃げ型 | Y2: =IF(X2="攻め型",1, IF(X2="差し型",1, IF(X2="逃げ型",1, IF(X2="脆い型",-1,0)))) -> 1 | Z2: =J2 + Y2 -> 20 | AA2: =IF( AND( I2 = 0, Z2 < MEDIAN($Z$2:$Z$7), OR( C2 < 0.5, D2 < 0.5 ) ), 1, 0 ) -> 0
A3: 2 | B3: 2 | C3: =C12 -> 0.714 | D3: =C14 -> 0.846 | E3: =TENJI!Q3 -> 28 | F3: =TENJI!S3 -> バランス | G3: =TENJI!R3 -> 0 | H3: =TENJI!T3 -> 0 | I3: =TENJI!U3 -> 0 | J3: =TENJI!V3 -> 28 | K3: =KIMARITE!C5 -> 0 | L3: =KIMARITE!D5 -> 0.095 | M3: =KIMARITE!E5 -> 0.048 | N3: =KIMARITE!F5 -> 0 | O3: =KIMARITE!G5 -> 0.524 | P3: =KIMARITE!H5 -> 0 | Q3: =KIMARITE!I5 -> 0 | R3: =KIMARITE!J5 -> 0 | S3: =(KIMARITE!L4 + KIMARITE!M4 + KIMARITE!N4) * (1 + (E3/100)) -> 0.288 | T3: =IF(AND(KIMARITE!$P$2>0.12, KIMARITE!L4>0.12), "★2差し", "-") -> ★2差し | U3: =IF(AND(KIMARITE!$Q$2>0.12, KIMARITE!M4>0.12), "🔥2まくり", "-") -> - | V3: =IF(AND(KIMARITE!$R$2>0.12, KIMARITE!N4>0.12), "✨2まくり差し", "-") -> - | W3: =IF(KIMARITE!G4>0.4, "🌓壁役(逃がし)", "-") -> 🌓壁役(逃がし) | X3: =IF(AND(K3>=0.2, B3=1),"逃げ型", IF(L3>=0.05,"差し型", IF(OR(M3>=0.05, N3>=0.05),"攻め型", IF(OR(P3>=0.2, R3>=0.2),"脆い型", "無色")))) -> 差し型 | Y3: =IF(X3="攻め型",1, IF(X3="差し型",1, IF(X3="逃げ型",1, IF(X3="脆い型",-1,0)))) -> 1 | Z3: =J3 + Y3 -> 29 | AA3: =IF( AND( I3 = 0, Z3 < MEDIAN($Z$2:$Z$7), OR( C3 < 0.5, D3 < 0.5 ) ), 1, 0 ) -> 0
A4: 3 | B4: 3 | C4: =D12 -> 0.643 | D4: =D14 -> 0.75 | E4: =TENJI!Q4 -> 24 | F4: =TENJI!S4 -> バランス | G4: =TENJI!R4 -> 0 | H4: =TENJI!T4 -> 0 | I4: =TENJI!U4 -> 1 | J4: =TENJI!V4 -> 25 | K4: =KIMARITE!C7 -> 0 | L4: =KIMARITE!D7 -> 0.071 | M4: =KIMARITE!E7 -> 0.071 | N4: =KIMARITE!F7 -> 0.071 | O4: =KIMARITE!G7 -> 0 | P4: =KIMARITE!H7 -> 0 | Q4: =KIMARITE!I7 -> 0 | R4: =KIMARITE!J7 -> 0 | S4: =(KIMARITE!L6+KIMARITE!M6+KIMARITE!N6)*(1+(E4/100)) -> 0.20708 | T4: =IF(AND(KIMARITE!$P$2>0.12, KIMARITE!L6>0.12), "★3差し", "-") -> - | U4: =IF(AND(KIMARITE!$Q$2>0.12, KIMARITE!M6>0.12), "🔥3まくり", "-") -> - | V4: =IF(AND(KIMARITE!$R$2>0.12, KIMARITE!N6>0.12), "✨3まくり差し", "-") -> - | W4: =IF(KIMARITE!G6>0.4, "🛡️外ブロック", "-") -> - | X4: =IF(AND(K4>=0.2, B4=1),"逃げ型", IF(L4>=0.05,"差し型", IF(OR(M4>=0.05, N4>=0.05),"攻め型", IF(OR(P4>=0.2, R4>=0.2),"脆い型", "無色")))) -> 差し型 | Y4: =IF(X4="攻め型",1, IF(X4="差し型",1, IF(X4="逃げ型",1, IF(X4="脆い型",-1,0)))) -> 1 | Z4: =J4 + Y4 -> 26 | AA4: =IF( AND( I4 = 0, Z4 < MEDIAN($Z$2:$Z$7), OR( C4 < 0.5, D4 < 0.5 ) ), 1, 0 ) -> 0
A5: 4 | B5: 4 | C5: =E12 -> 0.381 | D5: =E14 -> 0.5 | E5: =TENJI!Q5 -> 25 | F5: =TENJI!S5 -> 超伸び型 | G5: =TENJI!R5 -> 4 | H5: =TENJI!T5 -> 1 | I5: =TENJI!U5 -> 0 | J5: =TENJI!V5 -> 29 | K5: =KIMARITE!C9 -> 0 | L5: =KIMARITE!D9 -> 0 | M5: =KIMARITE!E9 -> 0 | N5: =KIMARITE!F9 -> 0 | O5: =KIMARITE!G9 -> 0 | P5: =KIMARITE!H9 -> 0 | Q5: =KIMARITE!I9 -> 0 | R5: =KIMARITE!J9 -> 0 | S5: =(KIMARITE!L8+KIMARITE!M8+KIMARITE!N8)*(1+(E5/100)) -> 0.1175 | T5: =IF(AND(KIMARITE!$P$2>0.12, KIMARITE!L8>0.12), "★4差し", "-") -> - | U5: =IF(AND(KIMARITE!$Q$2>0.12, KIMARITE!M8>0.12), "🔥4まくり", "-") -> - | V5: =IF(AND(KIMARITE!$R$2>0.12, KIMARITE!N8>0.12), "✨4まくり差し", "-") -> - | W5: - | X5: =IF(AND(K5>=0.2, B5=1),"逃げ型", IF(L5>=0.05,"差し型", IF(OR(M5>=0.05, N5>=0.05),"攻め型", IF(OR(P5>=0.2, R5>=0.2),"脆い型", "無色")))) -> 無色 | Y5: =IF(X5="攻め型",1, IF(X5="差し型",1, IF(X5="逃げ型",1, IF(X5="脆い型",-1,0)))) -> 0 | Z5: =J5 + Y5 -> 29 | AA5: =IF( AND( I5 = 0, Z5 < MEDIAN($Z$2:$Z$7), OR( C5 < 0.5, D5 < 0.5 ) ), 1, 0 ) -> 0
A6: 5 | B6: 5 | C6: =F12 -> 0.579 | D6: =F14 -> 0.6 | E6: =TENJI!Q6 -> 22 | F6: =TENJI!S6 -> バランス | G6: =TENJI!R6 -> 0 | H6: =TENJI!T6 -> 0 | I6: =TENJI!U6 -> 1 | J6: =TENJI!V6 -> 23 | K6: =KIMARITE!C11 -> 0 | L6: =KIMARITE!D11 -> 0 | M6: =KIMARITE!E11 -> 0.053 | N6: =KIMARITE!F11 -> 0.105 | O6: =KIMARITE!G11 -> 0 | P6: =KIMARITE!H11 -> 0 | Q6: =KIMARITE!I11 -> 0 | R6: =KIMARITE!J11 -> 0 | S6: =(KIMARITE!L10+KIMARITE!M10+KIMARITE!N10)*(1+(E6/100)) -> 0.16958 | T6: =IF(AND(KIMARITE!$P$2>0.12, KIMARITE!L10>0.12), "★5差し", "-") -> - | U6: =IF(AND(KIMARITE!$Q$2>0.12, KIMARITE!M10>0.12), "🔥5まくり", "-") -> - | V6: =IF(AND(KIMARITE!$R$2>0.12, KIMARITE!N10>0.12), "✨5まくり差し", "-") -> - | W6: - | X6: =IF(AND(K6>=0.2, B6=1),"逃げ型", IF(L6>=0.05,"差し型", IF(OR(M6>=0.05, N6>=0.05),"攻め型", IF(OR(P6>=0.2, R6>=0.2),"脆い型", "無色")))) -> 攻め型 | Y6: =IF(X6="攻め型",1, IF(X6="差し型",1, IF(X6="逃げ型",1, IF(X6="脆い型",-1,0)))) -> 1 | Z6: =J6 + Y6 -> 24 | AA6: =IF( AND( I6 = 0, Z6 < MEDIAN($Z$2:$Z$7), OR( C6 < 0.5, D6 < 0.5 ) ), 1, 0 ) -> 0
A7: 6 | B7: 6 | C7: =G12 -> 0.455 | D7: =G14 -> 0.667 | E7: =TENJI!Q7 -> 21 | F7: =TENJI!S7 -> バランス | G7: =TENJI!R7 -> 0 | H7: =TENJI!T7 -> 0 | I7: =TENJI!U7 -> 0 | J7: =TENJI!V7 -> 21 | K7: =KIMARITE!C13 -> 0 | L7: =KIMARITE!D13 -> 0 | M7: =KIMARITE!E13 -> 0 | N7: =KIMARITE!F13 -> 0 | O7: =KIMARITE!G13 -> 0 | P7: =KIMARITE!H13 -> 0 | Q7: =KIMARITE!I13 -> 0 | R7: =KIMARITE!J13 -> 0 | S7: =(KIMARITE!L12+KIMARITE!M12+KIMARITE!N12)*(1+(E7/100)) -> 0 | T7: =IF(AND(KIMARITE!$P$2>0.12, KIMARITE!L12>0.12), "★6差し", "-") -> - | U7: =IF(AND(KIMARITE!$Q$2>0.12, KIMARITE!M12>0.12), "🔥6まくり", "-") -> - | V7: =IF(AND(KIMARITE!$R$2>0.12, KIMARITE!N12>0.12), "✨6まくり差し", "-") -> - | W7: - | X7: =IF(AND(K7>=0.2, B7=1),"逃げ型", IF(L7>=0.05,"差し型", IF(OR(M7>=0.05, N7>=0.05),"攻め型", IF(OR(P7>=0.2, R7>=0.2),"脆い型", "無色")))) -> 無色 | Y7: =IF(X7="攻め型",1, IF(X7="差し型",1, IF(X7="逃げ型",1, IF(X7="脆い型",-1,0)))) -> 0 | Z7: =J7 + Y7 -> 21 | AA7: =IF( AND( I7 = 0, Z7 < MEDIAN($Z$2:$Z$7), OR( C7 < 0.5, D7 < 0.5 ) ), 1, 0 ) -> 1
A10: 3連対率をここに張る
A11: 3連対率(総合)
A12: 直近6ヶ月 | B12: 0.813 | C12: 0.714 | D12: 0.643 | E12: 0.381 | F12: 0.579 | G12: 0.455
B13: -32 | C13: -21 | D13: -14 | E13: -21 | F13: -19 | G13: -22
A14: 直近3ヶ月 | B14: 0.929 | C14: 0.846 | D14: 0.75 | E14: 0.5 | F14: 0.6 | G14: 0.667
B15: -14 | C15: -13 | D15: -4 | E15: -10 | F15: -10 | G15: -9

Sheet FORECAST (2)
A1: 艇番 | B1: 枠番 | C1: 直近6ヶ月3連対率 | D1: 直近3ヶ月3連対率 | E1: 展示総合スコア（R） | F1: 展示タイプ名（T） | G1: 展示タイプ補正（S） | H1: 展開キー（U） | I1: 展開もらい補正（V） | J1: 最終二次予想スコア（W） | K1: 逃げ率（6ヶ月） | L1: 差し率（6ヶ月） | M1: まくり率（6ヶ月） | N1: まくり差し率（6ヶ月） | O1: 逃し率（6ヶ月） | P1: 差され率（6ヶ月） | Q1: 捲られ率（6ヶ月） | R1: 捲られ差し率（6ヶ月） | S1: 期待値 | T1: 展開フラグ_差し | U1: 展開フラグ_まくり | V1: 展開フラグ_まくり差し | W1: 展開フラグ_逃し | X1: 決まり手タイプ | Y1: 決まり手補正（X） | Z1: 三次予想スコア | AA1: 切る艇
A2: 1 | B2: 1 | C2: =B12 -> 0.813 | D2: =B14 -> 0.929 | E2: =TENJI!Q2 -> 18 | F2: =TENJI!S2 -> バランス | G2: =TENJI!R2 -> 1 | H2: =TENJI!T2 -> 0 | I2: =TENJI!U2 -> 0 | J2: =TENJI!V2 -> 19 | K2: =KIMARITE!C3 -> 0.563 | L2: =KIMARITE!D3 -> 0 | M2: =KIMARITE!E3 -> 0 | N2: =KIMARITE!F3 -> 0 | O2: =KIMARITE!G3 -> 0 | P2: =KIMARITE!H3 -> 0.156 | Q2: =KIMARITE!I3 -> 0.25 | R2: =KIMARITE!J3 -> 0.031 | S2: =KIMARITE!K2 * (1 + (E2/100)) -> 0.54044 | T2: - | U2: - | V2: - | W2: - | X2: =IF(AND(K2>=0.2, B2=1),"逃げ型", IF(L2>=0.05,"差し型", IF(OR(M2>=0.05, N2>=0.05),"攻め型", IF(OR(P2>=0.2, R2>=0.2),"脆い型", "無色")))) -> 逃げ型 | Y2: =IF(X2="攻め型",1, IF(X2="差し型",1, IF(X2="逃げ型",1, IF(X2="脆い型",-1,0)))) -> 1 | Z2: =J2 + Y2 -> 20 | AA2: =IF( AND( I2 = 0, Z2 < MEDIAN($Z$2:$Z$7), OR( C2 < 0.5, D2 < 0.5 ) ), 1, 0 ) -> 0
A3: 2 | B3: 2 | C3: =C12 -> 0.714 | D3: =C14 -> 0.846 | E3: =TENJI!Q3 -> 28 | F3: =TENJI!S3 -> バランス | G3: =TENJI!R3 -> 0 | H3: =TENJI!T3 -> 0 | I3: =TENJI!U3 -> 0 | J3: =TENJI!V3 -> 28 | K3: =KIMARITE!C5 -> 0 | L3: =KIMARITE!D5 -> 0.095 | M3: =KIMARITE!E5 -> 0.048 | N3: =KIMARITE!F5 -> 0 | O3: =KIMARITE!G5 -> 0.524 | P3: =KIMARITE!H5 -> 0 | Q3: =KIMARITE!I5 -> 0 | R3: =KIMARITE!J5 -> 0 | S3: =(KIMARITE!L4 + KIMARITE!M4 + KIMARITE!N4) * (1 + (E3/100)) -> 0.288 | T3: =IF(AND(KIMARITE!$P$2>0.12, KIMARITE!L4>0.12), "★2差し", "-") -> ★2差し | U3: =IF(AND(KIMARITE!$Q$2>0.12, KIMARITE!M4>0.12), "🔥2まくり", "-") -> - | V3: =IF(AND(KIMARITE!$R$2>0.12, KIMARITE!N4>0.12), "✨2まくり差し", "-") -> - | W3: =IF(KIMARITE!G4>0.4, "🌓壁役(逃がし)", "-") -> 🌓壁役(逃がし) | X3: =IF(AND(K3>=0.2, B3=1),"逃げ型", IF(L3>=0.05,"差し型", IF(OR(M3>=0.05, N3>=0.05),"攻め型", IF(OR(P3>=0.2, R3>=0.2),"脆い型", "無色")))) -> 差し型 | Y3: =IF(X3="攻め型",1, IF(X3="差し型",1, IF(X3="逃げ型",1, IF(X3="脆い型",-1,0)))) -> 1 | Z3: =J3 + Y3 -> 29 | AA3: =IF( AND( I3 = 0, Z3 < MEDIAN($Z$2:$Z$7), OR( C3 < 0.5, D3 < 0.5 ) ), 1, 0 ) -> 0
A4: 3 | B4: 3 | C4: =D12 -> 0.643 | D4: =D14 -> 0.75 | E4: =TENJI!Q4 -> 24 | F4: =TENJI!S4 -> バランス | G4: =TENJI!R4 -> 0 | H4: =TENJI!T4 -> 0 | I4: =TENJI!U4 -> 1 | J4: =TENJI!V4 -> 25 | K4: =KIMARITE!C7 -> 0 | L4: =KIMARITE!D7 -> 0.071 | M4: =KIMARITE!E7 -> 0.071 | N4: =KIMARITE!F7 -> 0.071 | O4: =KIMARITE!G7 -> 0 | P4: =KIMARITE!H7 -> 0 | Q4: =KIMARITE!I7 -> 0 | R4: =KIMARITE!J7 -> 0 | S4: =(KIMARITE!L6+KIMARITE!M6+KIMARITE!N6)*(1+(E4/100)) -> 0.20708 | T4: =IF(AND(KIMARITE!$P$2>0.12, KIMARITE!L6>0.12), "★3差し", "-") -> - | U4: =IF(AND(KIMARITE!$Q$2>0.12, KIMARITE!M6>0.12), "🔥3まくり", "-") -> - | V4: =IF(AND(KIMARITE!$R$2>0.12, KIMARITE!N6>0.12), "✨3まくり差し", "-") -> - | W4: =IF(KIMARITE!G6>0.4, "🛡️外ブロック", "-") -> - | X4: =IF(AND(K4>=0.2, B4=1),"逃げ型", IF(L4>=0.05,"差し型", IF(OR(M4>=0.05, N4>=0.05),"攻め型", IF(OR(P4>=0.2, R4>=0.2),"脆い型", "無色")))) -> 差し型 | Y4: =IF(X4="攻め型",1, IF(X4="差し型",1, IF(X4="逃げ型",1, IF(X4="脆い型",-1,0)))) -> 1 | Z4: =J4 + Y4 -> 26 | AA4: =IF( AND( I4 = 0, Z4 < MEDIAN($Z$2:$Z$7), OR( C4 < 0.5, D4 < 0.5 ) ), 1, 0 ) -> 0
A5: 4 | B5: 4 | C5: =E12 -> 0.381 | D5: =E14 -> 0.5 | E5: =TENJI!Q5 -> 25 | F5: =TENJI!S5 -> 超伸び型 | G5: =TENJI!R5 -> 4 | H5: =TENJI!T5 -> 1 | I5: =TENJI!U5 -> 0 | J5: =TENJI!V5 -> 29 | K5: =KIMARITE!C9 -> 0 | L5: =KIMARITE!D9 -> 0 | M5: =KIMARITE!E9 -> 0 | N5: =KIMARITE!F9 -> 0 | O5: =KIMARITE!G9 -> 0 | P5: =KIMARITE!H9 -> 0 | Q5: =KIMARITE!I9 -> 0 | R5: =KIMARITE!J9 -> 0 | S5: =(KIMARITE!L8+KIMARITE!M8+KIMARITE!N8)*(1+(E5/100)) -> 0.1175 | T5: =IF(AND(KIMARITE!$P$2>0.12, KIMARITE!L8>0.12), "★4差し", "-") -> - | U5: =IF(AND(KIMARITE!$Q$2>0.12, KIMARITE!M8>0.12), "🔥4まくり", "-") -> - | V5: =IF(AND(KIMARITE!$R$2>0.12, KIMARITE!N8>0.12), "✨4まくり差し", "-") -> - | W5: - | X5: =IF(AND(K5>=0.2, B5=1),"逃げ型", IF(L5>=0.05,"差し型", IF(OR(M5>=0.05, N5>=0.05),"攻め型", IF(OR(P5>=0.2, R5>=0.2),"脆い型", "無色")))) -> 無色 | Y5: =IF(X5="攻め型",1, IF(X5="差し型",1, IF(X5="逃げ型",1, IF(X5="脆い型",-1,0)))) -> 0 | Z5: =J5 + Y5 -> 29 | AA5: =IF( AND( I5 = 0, Z5 < MEDIAN($Z$2:$Z$7), OR( C5 < 0.5, D5 < 0.5 ) ), 1, 0 ) -> 0
